Workbook

Sheet Methods and calculation
A1: Item | B1: Week1 | C1: Week2 | D1: Week3 | E1: Week4 | F1: Week5 | G1: Week6 | H1: Week7 | I1: Week8 | J1: Week9 | K1: Week10 | L1: Week11 | M1: Week12 | N1: Week13 | O1: Week14 | P1: Week15 | Q1: Week16 | R1: Week17 | S1: Week18 | T1: Week19 | U1: Week20 | V1: Week21 | W1: Week22 | X1: Week23 | Y1: Week24 | Z1: Week25 | AA1: Week26 | AB1: Week27 | AC1: Week28 | AD1: Week29 | AE1: Week30 | AF1: Week31 | AG1: Week32 | AH1: Week33 | AI1: Week34 | AJ1: Week35 | AK1: Week36 | AL1: Week37 | AM1: Week38 | AN1: Week39 | AO1: Week40 | AP1: Week41 | AQ1: Week42 | AR1: Week43 | AS1: Week44 | AT1: Week45 | AU1: Week46 | AV1: Week47 | AW1: Week48 | AX1: Week49 | AY1: Week50 | AZ1: Week51 | BA1: Week52 | BB1: Week53 | BC1: Week54 | BD1: Week55 | BE1: Week56 | BF1: Week57 | BG1: Week58 | BH1: Week59 | BI1: Week60 | BJ1: Week61 | BK1: Week62 | BL1: Week63 | BM1: Week64 | BN1: Week65 | BO1: Week66 | BP1: Week67 | BQ1: Week68 | BR1: Week69 | BS1: Week70 | BT1: Week71 | BU1: Week72 | BV1: Week73 | BW1: Week74 | BX1: Week75 | BY1: Week76 | BZ1: Week77 | CA1: Week78 | CB1: Week79 | CC1: Week80 | CD1: Week81 | CE1: Week82 | CF1: Week83 | CG1: Week84 | CH1: Week85 | CI1: Week86 | CJ1: Week87 | CK1: Week88 | CL1: Week89 | CM1: Week90 | CN1: Week91 | CO1: Week92 | CP1: Week93 | CQ1: Week94 | CR1: Week95 | CS1: Week96 | CT1: Week97 | CU1: Week98 | CV1: Week99 | CW1: Week100 | CX1: Week101 | CY1: Week102 | CZ1: Week103 | DA1: Week104 | DB1: Week105 | DC1: Week106 | DD1: Week107 | DE1: Week108 | DF1: Week109 | DG1: Week110
A2: A | B2: 3 | C2: 12 | D2: 41 | E2: 2 | F2: 31 | G2: 2 | H2: 43 | I2: 43 | J2: 22 | K2: 32 | L2: 3 | M2: 12 | N2: 41 | O2: 2 | P2: 31 | Q2: 2 | R2: 43 | S2: 43 | T2: 22 | U2: 32 | V2: 3 | W2: 12 | X2: 41 | Y2: 2 | Z2: 31 | AA2: 2 | AB2: 43 | AC2: 43 | AD2: 22 | AE2: 32 | AF2: 3 | AG2: 12 | AH2: 41 | AI2: 2 | AJ2: 31 | AK2: 2 | AL2: 43 | AM2: 43 | AN2: 22 | AO2: 32 | AP2: 3 | AQ2: 12 | AR2: 41 | AS2: 2 | AT2: 31 | AU2: 2 | AV2: 43 | AW2: 43 | AX2: 22 | AY2: 32 | AZ2: 3 | BA2: 12 | BB2: 41 | BC2: 2 | BD2: 31 | BE2: 2 | BF2: 43 | BG2: 43 | BH2: 22 | BI2: 32 | BJ2: 3 | BK2: 12 | BL2: 41 | BM2: 2 | BN2: 31 | BO2: 2 | BP2: 43 | BQ2: 43 | BR2: 22 | BS2: 32 | BT2: 3 | BU2: 12 | BV2: 41 | BW2: 2 | BX2: 31 | BY2: 2 | BZ2: 43 | CA2: 43 | CB2: 22 | CC2: 32 | CD2: 3 | CE2: 12 | CF2: 41 | CG2: 2 | CH2: 31 | CI2: 2 | CJ2: 43 | CK2: 43 | CL2: 22 | CM2: 32 | CN2: 3 | CO2: 12 | CP2: 41 | CQ2: 2 | CR2: 31 | CS2: 2 | CT2: 43 | CU2: 43 | CV2: 22 | CW2: 32 | CX2: 3 | CY2: 12 | CZ2: 41 | DA2: 2 | DB2: 31 | DC2: 2 | DD2: 43 | DE2: 43 | DF2: 22 | DG2: 32
A3: B | B3: 0 | C3: 0 | D3: 112 | E3: 2 | F3: 100 | G3: 33 | H3: 55 | I3: 53 | J3: 23 | K3: 12 | L3: 0 | M3: 0 | N3: 112 | O3: 2 | P3: 100 | Q3: 33 | R3: 55 | S3: 53 | T3: 23 | U3: 12 | V3: 0 | W3: 0 | X3: 112 | Y3: 2 | Z3: 100 | AA3: 33 | AB3: 55 | AC3: 53 | AD3: 23 | AE3: 12 | AF3: 0 | AG3: 0 | AH3: 112 | AI3: 2 | AJ3: 100 | AK3: 33 | AL3: 55 | AM3: 53 | AN3: 23 | AO3: 12 | AP3: 0 | AQ3: 0 | AR3: 112 | AS3: 2 | AT3: 100 | AU3: 33 | AV3: 55 | AW3: 53 | AX3: 23 | AY3: 12 | AZ3: 0 | BA3: 0 | BB3: 112 | BC3: 2 | BD3: 100 | BE3: 33 | BF3: 55 | BG3: 53 | BH3: 23 | BI3: 12 | BJ3: 0 | BK3: 0 | BL3: 112 | BM3: 2 | BN3: 100 | BO3: 33 | BP3: 55 | BQ3: 53 | BR3: 23 | BS3: 12 | BT3: 0 | BU3: 0 | BV3: 112 | BW3: 2 | BX3: 100 | BY3: 33 | BZ3: 55 | CA3: 53 | CB3: 23 | CC3: 12 | CD3: 0 | CE3: 0 | CF3: 112 | CG3: 2 | CH3: 100 | CI3: 33 | CJ3: 55 | CK3: 53 | CL3: 23 | CM3: 12 | CN3: 0 | CO3: 0 | CP3: 112 | CQ3: 2 | CR3: 100 | CS3: 33 | CT3: 55 | CU3: 53 | CV3: 23 | CW3: 12 | CX3: 0 | CY3: 0 | CZ3: 112 | DA3: 2 | DB3: 100 | DC3: 33 | DD3: 55 | DE3: 53 | DF3: 23 | DG3: 12
A4: C | B4: 916 | C4: 939 | D4: 305 | E4: 952 | F4: 128 | G4: 81 | H4: 908 | I4: 744 | J4: 333 | K4: 862 | L4: 606 | M4: 352 | N4: 233 | O4: 502 | P4: 693 | Q4: 828 | R4: 189 | S4: 89 | T4: 705 | U4: 486 | V4: 142 | W4: 575 | X4: 972 | Y4: 222 | Z4: 593 | AA4: 259 | AB4: 492 | AC4: 227 | AD4: 195 | AE4: 374 | AF4: 539 | AG4: 2 | AH4: 865 | AI4: 308 | AJ4: 118 | AK4: 126 | AL4: 881 | AM4: 126 | AN4: 645 | AO4: 868 | AP4: 943 | AQ4: 483 | AR4: 701 | AS4: 190 | AT4: 251 | AU4: 872 | AV4: 905 | AW4: 632 | AX4: 842 | AY4: 42 | AZ4: 517 | BA4: 950 | BB4: 891 | BC4: 536 | BD4: 462 | BE4: 916 | BF4: 939 | BG4: 305 | BH4: 952 | BI4: 128 | BJ4: 81 | BK4: 908 | BL4: 744 | BM4: 333 | BN4: 862 | BO4: 606 | BP4: 352 | BQ4: 233 | BR4: 502 | BS4: 693 | BT4: 828 | BU4: 189 | BV4: 89 | BW4: 705 | BX4: 486 | BY4: 142 | BZ4: 575 | CA4: 972 | CB4: 222 | CC4: 593 | CD4: 259 | CE4: 492 | CF4: 227 | CG4: 195 | CH4: 374 | CI4: 539 | CJ4: 2 | CK4: 865 | CL4: 308 | CM4: 118 | CN4: 126 | CO4: 881 | CP4: 126 | CQ4: 645 | CR4: 868 | CS4: 943 | CT4: 483 | CU4: 701 | CV4: 190 | CW4: 251 | CX4: 872 | CY4: 905 | CZ4: 632 | DA4: 842 | DB4: 42 | DC4: 517 | DD4: 950 | DE4: 891 | DF4: 536 | DG4: 462
A5: D | B5: 77 | C5: 322 | D5: 260 | E5: 233 | F5: 284 | G5: 399 | H5: 370 | I5: 209 | J5: 368 | K5: 240 | L5: 350 | M5: 402 | N5: 343 | O5: 204 | P5: 298 | Q5: 226 | R5: 235 | S5: 4 | T5: 478 | U5: 174 | V5: 451 | W5: 295 | X5: 77 | Y5: 322 | Z5: 260 | AA5: 233 | AB5: 284 | AC5: 399 | AD5: 370 | AE5: 209 | AF5: 368 | AG5: 240 | AH5: 350 | AI5: 402 | AJ5: 343 | AK5: 204 | AL5: 298 | AM5: 226 | AN5: 235 | AO5: 4 | AP5: 478 | AQ5: 174 | AR5: 451 | AS5: 295 | AT5: 77 | AU5: 322 | AV5: 260 | AW5: 233 | AX5: 284 | AY5: 399 | AZ5: 370 | BA5: 209 | BB5: 368 | BC5: 240 | BD5: 350 | BE5: 402 | BF5: 343 | BG5: 204 | BH5: 298 | BI5: 226 | BJ5: 235 | BK5: 4 | BL5: 478 | BM5: 174 | BN5: 451 | BO5: 295 | BP5: 77 | BQ5: 322 | BR5: 260 | BS5: 233 | BT5: 284 | BU5: 399 | BV5: 370 | BW5: 209 | BX5: 368 | BY5: 240 | BZ5: 350 | CA5: 402 | CB5: 343 | CC5: 204 | CD5: 298 | CE5: 226 | CF5: 235 | CG5: 4 | CH5: 478 | CI5: 174 | CJ5: 451 | CK5: 295 | CL5: 77 | CM5: 322 | CN5: 260 | CO5: 233 | CP5: 284 | CQ5: 399 | CR5: 370 | CS5: 209 | CT5: 368 | CU5: 240 | CV5: 350 | CW5: 402 | CX5: 343 | CY5: 204 | CZ5: 298 | DA5: 226 | DB5: 235 | DC5: 4 | DD5: 478 | DE5: 174 | DF5: 451 | DG5: 295
A6: E | B6: 779 | C6: 532 | D6: 86 | E6: 290 | F6: 534 | G6: 505 | H6: 249 | I6: 503 | J6: 991 | K6: 705 | L6: 357 | M6: 112 | N6: 927 | O6: 582 | P6: 746 | Q6: 677 | R6: 405 | S6: 758 | T6: 412 | U6: 890 | V6: 944 | W6: 818 | X6: 293 | Y6: 575 | Z6: 10 | AA6: 294 | AB6: 593 | AC6: 380 | AD6: 133 | AE6: 886 | AF6: 956 | AG6: 886 | AH6: 506 | AI6: 581 | AJ6: 558 | AK6: 879 | AL6: 322 | AM6: 613 | AN6: 613 | AO6: 888 | AP6: 592 | AQ6: 192 | AR6: 249 | AS6: 293 | AT6: 283 | AU6: 156 | AV6: 336 | AW6: 192 | AX6: 226 | AY6: 634 | AZ6: 713 | BA6: 961 | BB6: 41 | BC6: 988 | BD6: 628 | BE6: 286 | BF6: 90 | BG6: 350 | BH6: 312 | BI6: 127 | BJ6: 862 | BK6: 433 | BL6: 311 | BM6: 795 | BN6: 94 | BO6: 249 | BP6: 293 | BQ6: 825 | BR6: 986 | BS6: 360 | BT6: 590 | BU6: 435 | BV6: 713 | BW6: 40 | BX6: 881 | BY6: 942 | BZ6: 910 | CA6: 663 | CB6: 815 | CC6: 523 | CD6: 901 | CE6: 500 | CF6: 637 | CG6: 972 | CH6: 294 | CI6: 815 | CJ6: 860 | CK6: 736 | CL6: 929 | CM6: 650 | CN6: 396 | CO6: 541 | CP6: 471 | CQ6: 370 | CR6: 727 | CS6: 639 | CT6: 626 | CU6: 955 | CV6: 31 | CW6: 250 | CX6: 911 | CY6: 688 | CZ6: 677 | DA6: 788 | DB6: 650 | DC6: 734 | DD6: 543 | DE6: 337 | DF6: 514 | DG6: 126
CX9: Naive
A10: Item | B10: Week1 | C10: Week2 | D10: Week3 | E10: Week4 | F10: Week5 | G10: Week6 | H10: Week7 | I10: Week8 | J10: Week9 | K10: Week10 | L10: Week11 | M10: Week12 | N10: Week13 | O10: Week14 | P10: Week15 | Q10: Week16 | R10: Week17 | S10: Week18 | T10: Week19 | U10: Week20 | V10: Week21 | W10: Week22 | X10: Week23 | Y10: Week24 | Z10: Week25 | AA10: Week26 | AB10: Week27 | AC10: Week28 | AD10: Week29 | AE10: Week30 | AF10: Week31 | AG10: Week32 | AH10: Week33 | AI10: Week34 | AJ10: Week35 | AK10: Week36 | AL10: Week37 | AM10: Week38 | AN10: Week39 | AO10: Week40 | AP10: Week41 | AQ10: Week42 | AR10: Week43 | AS10: Week44 | AT10: Week45 | AU10: Week46 | AV10: Week47 | AW10: Week48 | AX10: Week49 | AY10: Week50 | AZ10: Week51 | BA10: Week52 | BB10: Week53 | BC10: Week54 | BD10: Week55 | BE10: Week56 | BF10: Week57 | BG10: Week58 | BH10: Week59 | BI10: Week60 | BJ10: Week61 | BK10: Week62 | BL10: Week63 | BM10: Week64 | BN10: Week65 | BO10: Week66 | BP10: Week67 | BQ10: Week68 | BR10: Week69 | BS10: Week70 | BT10: Week71 | BU10: Week72 | BV10: Week73 | BW10: Week74 | BX10: Week75 | BY10: Week76 | BZ10: Week77 | CA10: Week78 | CB10: Week79 | CC10: Week80 | CD10: Week81 | CE10: Week82 | CF10: Week83 | CG10: Week84 | CH10: Week85 | CI10: Week86 | CJ10: Week87 | CK10: Week88 | CL10: Week89 | CM10: Week90 | CN10: Week91 | CO10: Week92 | CP10: Week93 | CQ10: Week94 | CR10: Week95 | CS10: Week96 | CT10: Week97 | CU10: Week98 | CV10: Week99 | CW10: Week100 | CX10: Week101 | CY10: Week102 | CZ10: Week103 | DA10: Week104 | DB10: Week105 | DC10: Week106 | DD10: Week107 | DE10: Week108 | DF10: Week109 | DG10: Week110 | DH10: Diffrerence | DI10: Week101 | DJ10: Week102 | DK10: Week103 | DL10: Week104 | DM10: Week105 | DN10: Week106 | DO10: Week107 | DP10: Week108 | DQ10: Week109 | DR10: Week110 | DS10: Summarized | DZ10: Week101 | EA10: Week102 | EB10: Week103 | EC10: Week104 | ED10: Week105 | EE10: Week106 | EF10: Week107 | EG10: Week108 | EH10: Week109 | EI10: Week110 | EJ10: Summarized
A11: A | B11: 3 | C11: 12 | D11: 41 | E11: 2 | F11: 31 | G11: 2 | H11: 43 | I11: 43 | J11: 22 | K11: 32 | L11: 3 | M11: 12 | N11: 41 | O11: 2 | P11: 31 | Q11: 2 | R11: 43 | S11: 43 | T11: 22 | U11: 32 | V11: 3 | W11: 12 | X11: 41 | Y11: 2 | Z11: 31 | AA11: 2 | AB11: 43 | AC11: 43 | AD11: 22 | AE11: 32 | AF11: 3 | AG11: 12 | AH11: 41 | AI11: 2 | AJ11: 31 | AK11: 2 | AL11: 43 | AM11: 43 | AN11: 22 | AO11: 32 | AP11: 3 | AQ11: 12 | AR11: 41 | AS11: 2 | AT11: 31 | AU11: 2 | AV11: 43 | AW11: 43 | AX11: 22 | AY11: 32 | AZ11: 3 | BA11: 12 | BB11: 41 | BC11: 2 | BD11: 31 | BE11: 2 | BF11: 43 | BG11: 43 | BH11: 22 | BI11: 32 | BJ11: 3 | BK11: 12 | BL11: 41 | BM11: 2 | BN11: 31 | BO11: 2 | BP11: 43 | BQ11: 43 | BR11: 22 | BS11: 32 | BT11: 3 | BU11: 12 | BV11: 41 | BW11: 2 | BX11: 31 | BY11: 2 | BZ11: 43 | CA11: 43 | CB11: 22 | CC11: 32 | CD11: 3 | CE11: 12 | CF11: 41 | CG11: 2 | CH11: 31 | CI11: 2 | CJ11: 43 | CK11: 43 | CL11: 22 | CM11: 32 | CN11: 3 | CO11: 12 | CP11: 41 | CQ11: 2 | CR11: 31 | CS11: 2 | CT11: 43 | CU11: 43 | CV11: 22 | CW11: 32 | CX11: =CW11 -> 32 | CY11: =CX11 -> 32 | CZ11: =CY11 -> 32 | DA11: =CZ11 -> 32 | DB11: =DA11 -> 32 | DC11: =DB11 -> 32 | DD11: =DC11 -> 32 | DE11: =DD11 -> 32 | ... DG11: =DF11 -> 32 | DI11: =ABS(CX11-CX2) -> 29 | DJ11: =ABS(CY11-CY2) -> 20 | DK11: =ABS(CZ11-CZ2) -> 9 | DL11: =ABS(DA11-DA2) -> 30 | DM11: =ABS(DB11-DB2) -> 1 | DN11: =ABS(DC11-DC2) -> 30 | DO11: =ABS(DD11-DD2) -> 11 | DP11: =ABS(DE11-DE2) -> 11 | ... DR11: =ABS(DG11-DG2) -> 0 | DS11: =SUM(DI11:DR11) -> 151 | DZ11: =ABS(CX11-CX$2)/MAX($B$2:$CW$2) -> 0.6744186 | EA11: =ABS(CY11-CY$2)/MAX($B$2:$CW$2) -> 0.46511628 | EB11: =ABS(CZ11-CZ$2)/MAX($B$2:$CW$2) -> 0.20930233 | EC11: =ABS(DA11-DA$2)/MAX($B$2:$CW$2) -> 0.69767442 | ED11: =ABS(DB11-DB$2)/MAX($B$2:$CW$2) -> 0.023255814 | EE11: =ABS(DC11-DC$2)/MAX($B$2:$CW$2) -> 0.69767442 | EF11: =ABS(DD11-DD$2)/MAX($B$2:$CW$2) -> 0.25581395 | EG11: =ABS(DE11-DE$2)/MAX($B$2:$CW$2) -> 0.25581395 | ... EI11: =ABS(DG11-DG$2)/MAX($B$2:$CW$2) -> 0 | EJ11: =SUM(DZ11:EI11) -> 3.5116279
A12: B | B12: 0 | C12: 0 | D12: 112 | E12: 2 | F12: 100 | G12: 33 | H12: 55 | I12: 53 | J12: 23 | K12: 12 | L12: 0 | M12: 0 | N12: 112 | O12: 2 | P12: 100 | Q12: 33 | R12: 55 | S12: 53 | T12: 23 | U12: 12 | V12: 0 | W12: 0 | X12: 112 | Y12: 2 | Z12: 100 | AA12: 33 | AB12: 55 | AC12: 53 | AD12: 23 | AE12: 12 | AF12: 0 | AG12: 0 | AH12: 112 | AI12: 2 | AJ12: 100 | AK12: 33 | AL12: 55 | AM12: 53 | AN12: 23 | AO12: 12 | AP12: 0 | AQ12: 0 | AR12: 112 | AS12: 2 | AT12: 100 | AU12: 33 | AV12: 55 | AW12: 53 | AX12: 23 | AY12: 12 | AZ12: 0 | BA12: 0 | BB12: 112 | BC12: 2 | BD12: 100 | BE12: 33 | BF12: 55 | BG12: 53 | BH12: 23 | BI12: 12 | BJ12: 0 | BK12: 0 | BL12: 112 | BM12: 2 | BN12: 100 | BO12: 33 | BP12: 55 | BQ12: 53 | BR12: 23 | BS12: 12 | BT12: 0 | BU12: 0 | BV12: 112 | BW12: 2 | BX12: 100 | BY12: 33 | BZ12: 55 | CA12: 53 | CB12: 23 | CC12: 12 | CD12: 0 | CE12: 0 | CF12: 112 | CG12: 2 | CH12: 100 | CI12: 33 | CJ12: 55 | CK12: 53 | CL12: 23 | CM12: 12 | CN12: 0 | CO12: 0 | CP12: 112 | CQ12: 2 | CR12: 100 | CS12: 33 | CT12: 55 | CU12: 53 | CV12: 23 | CW12: 12 | CX12: =CW12 -> 12 | CY12: =CX12 -> 12 | CZ12: =CY12 -> 12 | DA12: =CZ12 -> 12 | DB12: =DA12 -> 12 | DC12: =DB12 -> 12 | DD12: =DC12 -> 12 | DE12: =DD12 -> 12 | ... DG12: =DF12 -> 12 | DI12: =ABS(CX12-CX3) -> 12 | DJ12: =ABS(CY12-CY3) -> 12 | DK12: =ABS(CZ12-CZ3) -> 100 | DL12: =ABS(DA12-DA3) -> 10 | DM12: =ABS(DB12-DB3) -> 88 | DN12: =ABS(DC12-DC3) -> 21 | DO12: =ABS(DD12-DD3) -> 43 | DP12: =ABS(DE12-DE3) -> 41 | ... DR12: =ABS(DG12-DG3) -> 0 | DS12: =SUM(DI12:DR12) -> 338 | DZ12: =ABS(CX12-CX$3)/MAX($B$3:$CW$3) -> 0.10714286 | EA12: =ABS(CY12-CY$3)/MAX($B$3:$CW$3) -> 0.10714286 | EB12: =ABS(CZ12-CZ$3)/MAX($B$3:$CW$3) -> 0.89285714 | EC12: =ABS(DA12-DA$3)/MAX($B$3:$CW$3) -> 0.089285714 | ED12: =ABS(DB12-DB$3)/MAX($B$3:$CW$3) -> 0.78571429 | EE12: =ABS(DC12-DC$3)/MAX($B$3:$CW$3) -> 0.1875 | EF12: =ABS(DD12-DD$3)/MAX($B$3:$CW$3) -> 0.38392857 | EG12: =ABS(DE12-DE$3)/MAX($B$3:$CW$3) -> 0.36607143 | ... EI12: =ABS(DG12-DG$3)/MAX($B$3:$CW$3) -> 0 | EJ12: =SUM(DZ12:EI12) -> 3.0178571
A13: C | B13: 916 | C13: 939 | D13: 305 | E13: 952 | F13: 128 | G13: 81 | H13: 908 | I13: 744 | J13: 333 | K13: 862 | L13: 606 | M13: 352 | N13: 233 | O13: 502 | P13: 693 | Q13: 828 | R13: 189 | S13: 89 | T13: 705 | U13: 486 | V13: 142 | W13: 575 | X13: 972 | Y13: 222 | Z13: 593 | AA13: 259 | AB13: 492 | AC13: 227 | AD13: 195 | AE13: 374 | AF13: 539 | AG13: 2 | AH13: 865 | AI13: 308 | AJ13: 118 | AK13: 126 | AL13: 881 | AM13: 126 | AN13: 645 | AO13: 868 | AP13: 943 | AQ13: 483 | AR13: 701 | AS13: 190 | AT13: 251 | AU13: 872 | AV13: 905 | AW13: 632 | AX13: 842 | AY13: 42 | AZ13: 517 | BA13: 950 | BB13: 891 | BC13: 536 | BD13: 462 | BE13: 916 | BF13: 939 | BG13: 305 | BH13: 952 | BI13: 128 | BJ13: 81 | BK13: 908 | BL13: 744 | BM13: 333 | BN13: 862 | BO13: 606 | BP13: 352 | BQ13: 233 | BR13: 502 | BS13: 693 | BT13: 828 | BU13: 189 | BV13: 89 | BW13: 705 | BX13: 486 | BY13: 142 | BZ13: 575 | CA13: 972 | CB13: 222 | CC13: 593 | CD13: 259 | CE13: 492 | CF13: 227 | CG13: 195 | CH13: 374 | CI13: 539 | CJ13: 2 | CK13: 865 | CL13: 308 | CM13: 118 | CN13: 126 | CO13: 881 | CP13: 126 | CQ13: 645 | CR13: 868 | CS13: 943 | CT13: 483 | CU13: 701 | CV13: 190 | CW13: 251 | CX13: =CW13 -> 251 | CY13: =CX13 -> 251 | CZ13: =CY13 -> 251 | DA13: =CZ13 -> 251 | DB13: =DA13 -> 251 | DC13: =DB13 -> 251 | DD13: =DC13 -> 251 | DE13: =DD13 -> 251 | ... DG13: =DF13 -> 251 | DI13: =ABS(CX13-CX4) -> 621 | DJ13: =ABS(CY13-CY4) -> 654 | DK13: =ABS(CZ13-CZ4) -> 381 | DL13: =ABS(DA13-DA4) -> 591 | DM13: =ABS(DB13-DB4) -> 209 | DN13: =ABS(DC13-DC4) -> 266 | DO13: =ABS(DD13-DD4) -> 699 | DP13: =ABS(DE13-DE4) -> 640 | ... DR13: =ABS(DG13-DG4) -> 211 | DS13: =SUM(DI13:DR13) -> 4557 | DZ13: =ABS(CX13-CX$4)/MAX($B$4:$CW$4) -> 0.63888889 | EA13: =ABS(CY13-CY$4)/MAX($B$4:$CW$4) -> 0.67283951 | EB13: =ABS(CZ13-CZ$4)/MAX($B$4:$CW$4) -> 0.39197531 | EC13: =ABS(DA13-DA$4)/MAX($B$4:$CW$4) -> 0.60802469 | ED13: =ABS(DB13-DB$4)/MAX($B$4:$CW$4) -> 0.21502058 | EE13: =ABS(DC13-DC$4)/MAX($B$4:$CW$4) -> 0.27366255 | EF13: =ABS(DD13-DD$4)/MAX($B$4:$CW$4) -> 0.7191358 | EG13: =ABS(DE13-DE$4)/MAX($B$4:$CW$4) -> 0.65843621 | ... EI13: =ABS(DG13-DG$4)/MAX($B$4:$CW$4) -> 0.21707819 | EJ13: =SUM(DZ13:EI13) -> 4.6882716
A14: D | B14: 77 | C14: 322 | D14: 260 | E14: 233 | F14: 284 | G14: 399 | H14: 370 | I14: 209 | J14: 368 | K14: 240 | L14: 350 | M14: 402 | N14: 343 | O14: 204 | P14: 298 | Q14: 226 | R14: 235 | S14: 4 | T14: 478 | U14: 174 | V14: 451 | W14: 295 | X14: 77 | Y14: 322 | Z14: 260 | AA14: 233 | AB14: 284 | AC14: 399 | AD14: 370 | AE14: 209 | AF14: 368 | AG14: 240 | AH14: 350 | AI14: 402 | AJ14: 343 | AK14: 204 | AL14: 298 | AM14: 226 | AN14: 235 | AO14: 4 | AP14: 478 | AQ14: 174 | AR14: 451 | AS14: 295 | AT14: 77 | AU14: 322 | AV14: 260 | AW14: 233 | AX14: 284 | AY14: 399 | AZ14: 370 | BA14: 209 | BB14: 368 | BC14: 240 | BD14: 350 | BE14: 402 | BF14: 343 | BG14: 204 | BH14: 298 | BI14: 226 | BJ14: 235 | BK14: 4 | BL14: 478 | BM14: 174 | BN14: 451 | BO14: 295 | BP14: 77 | BQ14: 322 | BR14: 260 | BS14: 233 | BT14: 284 | BU14: 399 | BV14: 370 | BW14: 209 | BX14: 368 | BY14: 240 | BZ14: 350 | CA14: 402 | CB14: 343 | CC14: 204 | CD14: 298 | CE14: 226 | CF14: 235 | CG14: 4 | CH14: 478 | CI14: 174 | CJ14: 451 | CK14: 295 | CL14: 77 | CM14: 322 | CN14: 260 | CO14: 233 | CP14: 284 | CQ14: 399 | CR14: 370 | CS14: 209 | CT14: 368 | CU14: 240 | CV14: 350 | CW14: 402 | CX14: =CW14 -> 402 | CY14: =CX14 -> 402 | CZ14: =CY14 -> 402 | DA14: =CZ14 -> 402 | DB14: =DA14 -> 402 | DC14: =DB14 -> 402 | DD14: =DC14 -> 402 | DE14: =DD14 -> 402 | ... DG14: =DF14 -> 402 | DI14: =ABS(CX14-CX5) -> 59 | DJ14: =ABS(CY14-CY5) -> 198 | DK14: =ABS(CZ14-CZ5) -> 104 | DL14: =ABS(DA14-DA5) -> 176 | DM14: =ABS(DB14-DB5) -> 167 | DN14: =ABS(DC14-DC5) -> 398 | DO14: =ABS(DD14-DD5) -> 76 | DP14: =ABS(DE14-DE5) -> 228 | ... DR14: =ABS(DG14-DG5) -> 107 | DS14: =SUM(DI14:DR14) -> 1562 | DZ14: =ABS(CX14-CX$5)/MAX($B$5:$CW$5) -> 0.12343096 | EA14: =ABS(CY14-CY$5)/MAX($B$5:$CW$5) -> 0.41422594 | EB14: =ABS(CZ14-CZ$5)/MAX($B$5:$CW$5) -> 0.21757322 | EC14: =ABS(DA14-DA$5)/MAX($B$5:$CW$5) -> 0.36820084 | ED14: =ABS(DB14-DB$5)/MAX($B$5:$CW$5) -> 0.34937238 | EE14: =ABS(DC14-DC$5)/MAX($B$5:$CW$5) -> 0.83263598 | EF14: =ABS(DD14-DD$5)/MAX($B$5:$CW$5) -> 0.15899582 | EG14: =ABS(DE14-DE$5)/MAX($B$5:$CW$5) -> 0.47698745 | ... EI14: =ABS(DG14-DG$5)/MAX($B$5:$CW$5) -> 0.22384937 | EJ14: =SUM(DZ14:EI14) -> 3.2677824
A15: E | B15: 779 | C15: 532 | D15: 86 | E15: 290 | F15: 534 | G15: 505 | H15: 249 | I15: 503 | J15: 991 | K15: 705 | L15: 357 | M15: 112 | N15: 927 | O15: 582 | P15: 746 | Q15: 677 | R15: 405 | S15: 758 | T15: 412 | U15: 890 | V15: 944 | W15: 818 | X15: 293 | Y15: 575 | Z15: 10 | AA15: 294 | AB15: 593 | AC15: 380 | AD15: 133 | AE15: 886 | AF15: 956 | AG15: 886 | AH15: 506 | AI15: 581 | AJ15: 558 | AK15: 879 | AL15: 322 | AM15: 613 | AN15: 613 | AO15: 888 | AP15: 592 | AQ15: 192 | AR15: 249 | AS15: 293 | AT15: 283 | AU15: 156 | AV15: 336 | AW15: 192 | AX15: 226 | AY15: 634 | AZ15: 713 | BA15: 961 | BB15: 41 | BC15: 988 | BD15: 628 | BE15: 286 | BF15: 90 | BG15: 350 | BH15: 312 | BI15: 127 | BJ15: 862 | BK15: 433 | BL15: 311 | BM15: 795 | BN15: 94 | BO15: 249 | BP15: 293 | BQ15: 825 | BR15: 986 | BS15: 360 | BT15: 590 | BU15: 435 | BV15: 713 | BW15: 40 | BX15: 881 | BY15: 942 | BZ15: 910 | CA15: 663 | CB15: 815 | CC15: 523 | CD15: 901 | CE15: 500 | CF15: 637 | CG15: 972 | CH15: 294 | CI15: 815 | CJ15: 860 | CK15: 736 | CL15: 929 | CM15: 650 | CN15: 396 | CO15: 541 | CP15: 471 | CQ15: 370 | CR15: 727 | CS15: 639 | CT15: 626 | CU15: 955 | CV15: 31 | CW15: 250 | CX15: =CW15 -> 250 | CY15: =CX15 -> 250 | CZ15: =CY15 -> 250 | DA15: =CZ15 -> 250 | DB15: =DA15 -> 250 | DC15: =DB15 -> 250 | DD15: =DC15 -> 250 | DE15: =DD15 -> 250 | ... DG15: =DF15 -> 250 | DI15: =ABS(CX15-CX6) -> 661 | DJ15: =ABS(CY15-CY6) -> 438 | DK15: =ABS(CZ15-CZ6) -> 427 | DL15: =ABS(DA15-DA6) -> 538 | DM15: =ABS(DB15-DB6) -> 400 | DN15: =ABS(DC15-DC6) -> 484 | DO15: =ABS(DD15-DD6) -> 293 | DP15: =ABS(DE15-DE6) -> 87 | ... DR15: =ABS(DG15-DG6) -> 124 | DS15: =SUM(DI15:DR15) -> 3716 | DZ15: =ABS(CX15-CX$6)/MAX($B$6:$CW$6) -> 0.66700303 | EA15: =ABS(CY15-CY$6)/MAX($B$6:$CW$6) -> 0.4419778 | EB15: =ABS(CZ15-CZ$6)/MAX($B$6:$CW$6) -> 0.4308779 | EC15: =ABS(DA15-DA$6)/MAX($B$6:$CW$6) -> 0.54288597 | ED15: =ABS(DB15-DB$6)/MAX($B$6:$CW$6) -> 0.40363269 | EE15: =ABS(DC15-DC$6)/MAX($B$6:$CW$6) -> 0.48839556 | EF15: =ABS(DD15-DD$6)/MAX($B$6:$CW$6) -> 0.29566095 | EG15: =ABS(DE15-DE$6)/MAX($B$6:$CW$6) -> 0.087790111 | ... EI15: =ABS(DG15-DG$6)/MAX($B$6:$CW$6) -> 0.12512614 | EJ15: =SUM(DZ15:EI15) -> 3.7497477
CX18: MA
A19: Item | B19: Week1 | C19: Week2 | D19: Week3 | E19: Week4 | F19: Week5 | G19: Week6 | H19: Week7 | I19: Week8 | J19: Week9 | K19: Week10 | L19: Week11 | M19: Week12 | N19: Week13 | O19: Week14 | P19: Week15 | Q19: Week16 | R19: Week17 | S19: Week18 | T19: Week19 | U19: Week20 | V19: Week21 | W19: Week22 | X19: Week23 | Y19: Week24 | Z19: Week25 | AA19: Week26 | AB19: Week27 | AC19: Week28 | AD19: Week29 | AE19: Week30 | AF19: Week31 | AG19: Week32 | AH19: Week33 | AI19: Week34 | AJ19: Week35 | AK19: Week36 | AL19: Week37 | AM19: Week38 | AN19: Week39 | AO19: Week40 | AP19: Week41 | AQ19: Week42 | AR19: Week43 | AS19: Week44 | AT19: Week45 | AU19: Week46 | AV19: Week47 | AW19: Week48 | AX19: Week49 | AY19: Week50 | AZ19: Week51 | BA19: Week52 | BB19: Week53 | BC19: Week54 | BD19: Week55 | BE19: Week56 | BF19: Week57 | BG19: Week58 | BH19: Week59 | BI19: Week60 | BJ19: Week61 | BK19: Week62 | BL19: Week63 | BM19: Week64 | BN19: Week65 | BO19: Week66 | BP19: Week67 | BQ19: Week68 | BR19: Week69 | BS19: Week70 | BT19: Week71 | BU19: Week72 | BV19: Week73 | BW19: Week74 | BX19: Week75 | BY19: Week76 | BZ19: Week77 | CA19: Week78 | CB19: Week79 | CC19: Week80 | CD19: Week81 | CE19: Week82 | CF19: Week83 | CG19: Week84 | CH19: Week85 | CI19: Week86 | CJ19: Week87 | CK19: Week88 | CL19: Week89 | CM19: Week90 | CN19: Week91 | CO19: Week92 | CP19: Week93 | CQ19: Week94 | CR19: Week95 | CS19: Week96 | CT19: Week97 | CU19: Week98 | CV19: Week99 | CW19: Week100 | CX19: Week101 | CY19: Week102 | CZ19: Week103 | DA19: Week104 | DB19: Week105 | DC19: Week106 | DD19: Week107 | DE19: Week108 | DF19: Week109 | DG19: Week110 | DH19: Diffrerence | DI19: Week101 | DJ19: Week102 | DK19: Week103 | DL19: Week104 | DM19: Week105 | DN19: Week106 | DO19: Week107 | DP19: Week108 | DQ19: Week109 | DR19: Week110 | DS19: Summarized | DU19: Moving average number | DZ19: Week101 | EA19: Week102 | EB19: Week103 | EC19: Week104 | ED19: Week105 | EE19: Week106 | EF19: Week107 | EG19: Week108 | EH19: Week109 | EI19: Week110 | EJ19: Summarized
A20: A | B20: 3 | C20: 12 | D20: 41 | E20: 2 | F20: 31 | G20: 2 | H20: 43 | I20: 43 | J20: 22 | K20: 32 | L20: 3 | M20: 12 | N20: 41 | O20: 2 | P20: 31 | Q20: 2 | R20: 43 | S20: 43 | T20: 22 | U20: 32 | V20: 3 | W20: 12 | X20: 41 | Y20: 2 | Z20: 31 | AA20: 2 | AB20: 43 | AC20: 43 | AD20: 22 | AE20: 32 | AF20: 3 | AG20: 12 | AH20: 41 | AI20: 2 | AJ20: 31 | AK20: 2 | AL20: 43 | AM20: 43 | AN20: 22 | AO20: 32 | AP20: 3 | AQ20: 12 | AR20: 41 | AS20: 2 | AT20: 31 | AU20: 2 | AV20: 43 | AW20: 43 | AX20: 22 | AY20: 32 | AZ20: 3 | BA20: 12 | BB20: 41 | BC20: 2 | BD20: 31 | BE20: 2 | BF20: 43 | BG20: 43 | BH20: 22 | BI20: 32 | BJ20: 3 | BK20: 12 | BL20: 41 | BM20: 2 | BN20: 31 | BO20: 2 | BP20: 43 | BQ20: 43 | BR20: 22 | BS20: 32 | BT20: 3 | BU20: 12 | BV20: 41 | BW20: 2 | BX20: 31 | BY20: 2 | BZ20: 43 | CA20: 43 | CB20: 22 | CC20: 32 | CD20: 3 | CE20: 12 | CF20: 41 | CG20: 2 | CH20: 31 | CI20: 2 | CJ20: 43 | CK20: 43 | CL20: 22 | CM20: 32 | CN20: 3 | CO20: 12 | CP20: 41 | CQ20: 2 | CR20: 31 | CS20: 2 | CT20: 43 | CU20: 43 | CV20: 22 | CW20: 32 | CX20: =AVERAGE(CO20:CW20) -> 25.333333 | CY20: =AVERAGE(CQ20:CX20) -> 25.041667 | CZ20: =AVERAGE(CR20:CY20) -> 27.921875 | DA20: =AVERAGE(CS20:CZ20) -> 27.537109 | DB20: =AVERAGE(CT20:DA20) -> 30.729248 | DC20: =AVERAGE(CU20:DB20) -> 29.195404 | DD20: =AVERAGE(CV20:DC20) -> 27.46983 | DE20: =AVERAGE(CW20:DD20) -> 28.153558 | DF20: =AVERAGE(CX20:DE20) -> 27.672753 | DG20: =AVERAGE(CY20:DF20) -> 27.96518 | DI20: =ABS(CX20-CX2) -> 22.333333 | DJ20: =ABS(CY20-CY2) -> 13.041667 | DK20: =ABS(CZ20-CZ2) -> 13.078125 | DL20: =ABS(DA20-DA2) -> 25.537109 | DM20: =ABS(DB20-DB2) -> 0.27075195 | DN20: =ABS(DC20-DC2) -> 27.195404 | DO20: =ABS(DD20-DD2) -> 15.53017 | DP20: =ABS(DE20-DE2) -> 14.846442 | ... DR20: =ABS(DG20-DG2) -> 4.0348195 | DS20: =SUM(DI20:DR20) -> 141.54058 | DU20: 9 | DZ20: =ABS(CX20-CX$2)/MAX($B$2:$CW$2) -> 0.51937984 | EA20: =ABS(CY20-CY$2)/MAX($B$2:$CW$2) -> 0.30329457 | EB20: =ABS(CZ20-CZ$2)/MAX($B$2:$CW$2) -> 0.30414244 | EC20: =ABS(DA20-DA$2)/MAX($B$2:$CW$2) -> 0.59388626 | ED20: =ABS(DB20-DB$2)/MAX($B$2:$CW$2) -> 0.006296557 | EE20: =ABS(DC20-DC$2)/MAX($B$2:$CW$2) -> 0.63245126 | EF20: =ABS(DD20-DD$2)/MAX($B$2:$CW$2) -> 0.36116675 | EG20: =ABS(DE20-DE$2)/MAX($B$2:$CW$2) -> 0.34526609 | ... EI20: =ABS(DG20-DG$2)/MAX($B$2:$CW$2) -> 0.093833012 | EJ20: =SUM(DZ20:EI20) -> 3.2916413
A21: B | B21: 0 | C21: 0 | D21: 112 | E21: 2 | F21: 100 | G21: 33 | H21: 55 | I21: 53 | J21: 23 | K21: 12 | L21: 0 | M21: 0 | N21: 112 | O21: 2 | P21: 100 | Q21: 33 | R21: 55 | S21: 53 | T21: 23 | U21: 12 | V21: 0 | W21: 0 | X21: 112 | Y21: 2 | Z21: 100 | AA21: 33 | AB21: 55 | AC21: 53 | AD21: 23 | AE21: 12 | AF21: 0 | AG21: 0 | AH21: 112 | AI21: 2 | AJ21: 100 | AK21: 33 | AL21: 55 | AM21: 53 | AN21: 23 | AO21: 12 | AP21: 0 | AQ21: 0 | AR21: 112 | AS21: 2 | AT21: 100 | AU21: 33 | AV21: 55 | AW21: 53 | AX21: 23 | AY21: 12 | AZ21: 0 | BA21: 0 | BB21: 112 | BC21: 2 | BD21: 100 | BE21: 33 | BF21: 55 | BG21: 53 | BH21: 23 | BI21: 12 | BJ21: 0 | BK21: 0 | BL21: 112 | BM21: 2 | BN21: 100 | BO21: 33 | BP21: 55 | BQ21: 53 | BR21: 23 | BS21: 12 | BT21: 0 | BU21: 0 | BV21: 112 | BW21: 2 | BX21: 100 | BY21: 33 | BZ21: 55 | CA21: 53 | CB21: 23 | CC21: 12 | CD21: 0 | CE21: 0 | CF21: 112 | CG21: 2 | CH21: 100 | CI21: 33 | CJ21: 55 | CK21: 53 | CL21: 23 | CM21: 12 | CN21: 0 | CO21: 0 | CP21: 112 | CQ21: 2 | CR21: 100 | CS21: 33 | CT21: 55 | CU21: 53 | CV21: 23 | CW21: 12 | CX21: =AVERAGE(CT21:CW21) -> 35.75 | CY21: =AVERAGE(CT21:CX21) -> 35.75 | CZ21: =AVERAGE(CU21:CY21) -> 31.9 | DA21: =AVERAGE(CV21:CZ21) -> 27.68 | DB21: =AVERAGE(CW21:DA21) -> 28.616 | DC21: =AVERAGE(CX21:DB21) -> 31.9392 | DD21: =AVERAGE(CY21:DC21) -> 31.17704 | DE21: =AVERAGE(CZ21:DD21) -> 30.262448 | DF21: =AVERAGE(DA21:DE21) -> 29.934938 | DG21: =AVERAGE(DB21:DF21) -> 30.385925 | DI21: =ABS(CX21-CX3) -> 35.75 | DJ21: =ABS(CY21-CY3) -> 35.75 | DK21: =ABS(CZ21-CZ3) -> 80.1 | DL21: =ABS(DA21-DA3) -> 25.68 | DM21: =ABS(DB21-DB3) -> 71.384 | DN21: =ABS(DC21-DC3) -> 1.0608 | DO21: =ABS(DD21-DD3) -> 23.82296 | DP21: =ABS(DE21-DE3) -> 22.737552 | ... DR21: =ABS(DG21-DG3) -> 18.385925 | DS21: =SUM(DI21:DR21) -> 321.60617 | DU21: 4 | DZ21: =ABS(CX21-CX$3)/MAX($B$3:$CW$3) -> 0.31919643 | EA21: =ABS(CY21-CY$3)/MAX($B$3:$CW$3) -> 0.31919643 | EB21: =ABS(CZ21-CZ$3)/MAX($B$3:$CW$3) -> 0.71517857 | EC21: =ABS(DA21-DA$3)/MAX($B$3:$CW$3) -> 0.22928571 | ED21: =ABS(DB21-DB$3)/MAX($B$3:$CW$3) -> 0.63735714 | EE21: =ABS(DC21-DC$3)/MAX($B$3:$CW$3) -> 0.0094714286 | EF21: =ABS(DD21-DD$3)/MAX($B$3:$CW$3) -> 0.212705 | EG21: =ABS(DE21-DE$3)/MAX($B$3:$CW$3) -> 0.20301386 | ... EI21: =ABS(DG21-DG$3)/MAX($B$3:$CW$3) -> 0.16416005 | EJ21: =SUM(DZ21:EI21) -> 2.8714837
A22: C | B22: 916 | C22: 939 | D22: 305 | E22: 952 | F22: 128 | G22: 81 | H22: 908 | I22: 744 | J22: 333 | K22: 862 | L22: 606 | M22: 352 | N22: 233 | O22: 502 | P22: 693 | Q22: 828 | R22: 189 | S22: 89 | T22: 705 | U22: 486 | V22: 142 | W22: 575 | X22: 972 | Y22: 222 | Z22: 593 | AA22: 259 | AB22: 492 | AC22: 227 | AD22: 195 | AE22: 374 | AF22: 539 | AG22: 2 | AH22: 865 | AI22: 308 | AJ22: 118 | AK22: 126 | AL22: 881 | AM22: 126 | AN22: 645 | AO22: 868 | AP22: 943 | AQ22: 483 | AR22: 701 | AS22: 190 | AT22: 251 | AU22: 872 | AV22: 905 | AW22: 632 | AX22: 842 | AY22: 42 | AZ22: 517 | BA22: 950 | BB22: 891 | BC22: 536 | BD22: 462 | BE22: 916 | BF22: 939 | BG22: 305 | BH22: 952 | BI22: 128 | BJ22: 81 | BK22: 908 | BL22: 744 | BM22: 333 | BN22: 862 | BO22: 606 | BP22: 352 | BQ22: 233 | BR22: 502 | BS22: 693 | BT22: 828 | BU22: 189 | BV22: 89 | BW22: 705 | BX22: 486 | BY22: 142 | BZ22: 575 | CA22: 972 | CB22: 222 | CC22: 593 | CD22: 259 | CE22: 492 | CF22: 227 | CG22: 195 | CH22: 374 | CI22: 539 | CJ22: 2 | CK22: 865 | CL22: 308 | CM22: 118 | CN22: 126 | CO22: 881 | CP22: 126 | CQ22: 645 | CR22: 868 | CS22: 943 | CT22: 483 | CU22: 701 | CV22: 190 | CW22: 251 | CX22: =AVERAGE(CT22:CW22) -> 406.25 | CY22: =AVERAGE(CU22:CX22) -> 387.0625 | CZ22: =AVERAGE(CV22:CY22) -> 308.57812 | DA22: =AVERAGE(CW22:CZ22) -> 338.22266 | DB22: =AVERAGE(CX22:DA22) -> 360.02832 | DC22: =AVERAGE(CY22:DB22) -> 348.4729 | DD22: =AVERAGE(CZ22:DC22) -> 338.8255 | DE22: =AVERAGE(DA22:DD22) -> 346.38734 | ... DG22: =AVERAGE(DC22:DF22) -> 345.52857 | DI22: =ABS(CX22-CX4) -> 465.75 | DJ22: =ABS(CY22-CY4) -> 517.9375 | DK22: =ABS(CZ22-CZ4) -> 323.42188 | DL22: =ABS(DA22-DA4) -> 503.77734 | DM22: =ABS(DB22-DB4) -> 318.02832 | DN22: =ABS(DC22-DC4) -> 168.5271 | DO22: =ABS(DD22-DD4) -> 611.1745 | DP22: =ABS(DE22-DE4) -> 544.61266 | ... DR22: =ABS(DG22-DG4) -> 116.47143 | DS22: =SUM(DI22:DR22) -> 3757.2722 | DU22: 4 | DZ22: =ABS(CX22-CX$4)/MAX($B$4:$CW$4) -> 0.47916667 | EA22: =ABS(CY22-CY$4)/MAX($B$4:$CW$4) -> 0.53285751 | EB22: =ABS(CZ22-CZ$4)/MAX($B$4:$CW$4) -> 0.33273855 | EC22: =ABS(DA22-DA$4)/MAX($B$4:$CW$4) -> 0.51828945 | ED22: =ABS(DB22-DB$4)/MAX($B$4:$CW$4) -> 0.32718963 | EE22: =ABS(DC22-DC$4)/MAX($B$4:$CW$4) -> 0.17338179 | EF22: =ABS(DD22-DD$4)/MAX($B$4:$CW$4) -> 0.62878035 | EG22: =ABS(DE22-DE$4)/MAX($B$4:$CW$4) -> 0.56030109 | ... EI22: =ABS(DG22-DG$4)/MAX($B$4:$CW$4) -> 0.11982658 | EJ22: =SUM(DZ22:EI22) -> 3.8655064
A23: D | B23: 77 | C23: 322 | D23: 260 | E23: 233 | F23: 284 | G23: 399 | H23: 370 | I23: 209 | J23: 368 | K23: 240 | L23: 350 | M23: 402 | N23: 343 | O23: 204 | P23: 298 | Q23: 226 | R23: 235 | S23: 4 | T23: 478 | U23: 174 | V23: 451 | W23: 295 | X23: 77 | Y23: 322 | Z23: 260 | AA23: 233 | AB23: 284 | AC23: 399 | AD23: 370 | AE23: 209 | AF23: 368 | AG23: 240 | AH23: 350 | AI23: 402 | AJ23: 343 | AK23: 204 | AL23: 298 | AM23: 226 | AN23: 235 | AO23: 4 | AP23: 478 | AQ23: 174 | AR23: 451 | AS23: 295 | AT23: 77 | AU23: 322 | AV23: 260 | AW23: 233 | AX23: 284 | AY23: 399 | AZ23: 370 | BA23: 209 | BB23: 368 | BC23: 240 | BD23: 350 | BE23: 402 | BF23: 343 | BG23: 204 | BH23: 298 | BI23: 226 | BJ23: 235 | BK23: 4 | BL23: 478 | BM23: 174 | BN23: 451 | BO23: 295 | BP23: 77 | BQ23: 322 | BR23: 260 | BS23: 233 | BT23: 284 | BU23: 399 | BV23: 370 | BW23: 209 | BX23: 368 | BY23: 240 | BZ23: 350 | CA23: 402 | CB23: 343 | CC23: 204 | CD23: 298 | CE23: 226 | CF23: 235 | CG23: 4 | CH23: 478 | CI23: 174 | CJ23: 451 | CK23: 295 | CL23: 77 | CM23: 322 | CN23: 260 | CO23: 233 | CP23: 284 | CQ23: 399 | CR23: 370 | CS23: 209 | CT23: 368 | CU23: 240 | CV23: 350 | CW23: 402 | CX23: =AVERAGE(CP23:CW23) -> 327.75 | CY23: =AVERAGE(CQ23:CX23) -> 333.21875 | CZ23: =AVERAGE(CR23:CY23) -> 324.99609 | DA23: =AVERAGE(CS23:CZ23) -> 319.37061 | DB23: =AVERAGE(CT23:DA23) -> 333.16693 | DC23: =AVERAGE(CU23:DB23) -> 328.8128 | DD23: =AVERAGE(CV23:DC23) -> 339.9144 | DE23: =AVERAGE(CW23:DD23) -> 338.6537 | ... DG23: =AVERAGE(CY23:DF23) -> 331.10859 | DI23: =ABS(CX23-CX5) -> 15.25 | DJ23: =ABS(CY23-CY5) -> 129.21875 | DK23: =ABS(CZ23-CZ5) -> 26.996094 | DL23: =ABS(DA23-DA5) -> 93.370605 | DM23: =ABS(DB23-DB5) -> 98.166931 | DN23: =ABS(DC23-DC5) -> 324.8128 | DO23: =ABS(DD23-DD5) -> 138.0856 | DP23: =ABS(DE23-DE5) -> 164.6537 | ... DR23: =ABS(DG23-DG5) -> 36.108585 | DS23: =SUM(DI23:DR23) -> 1146.9277 | DU23: 8 | DZ23: =ABS(CX23-CX$5)/MAX($B$5:$CW$5) -> 0.031903766 | EA23: =ABS(CY23-CY$5)/MAX($B$5:$CW$5) -> 0.27033211 | EB23: =ABS(CZ23-CZ$5)/MAX($B$5:$CW$5) -> 0.056477184 | EC23: =ABS(DA23-DA$5)/MAX($B$5:$CW$5) -> 0.19533599 | ED23: =ABS(DB23-DB$5)/MAX($B$5:$CW$5) -> 0.20537015 | EE23: =ABS(DC23-DC$5)/MAX($B$5:$CW$5) -> 0.67952468 | EF23: =ABS(DD23-DD$5)/MAX($B$5:$CW$5) -> 0.28888201 | EG23: =ABS(DE23-DE$5)/MAX($B$5:$CW$5) -> 0.3444638 | ... EI23: =ABS(DG23-DG$5)/MAX($B$5:$CW$5) -> 0.075540973 | EJ23: =SUM(DZ23:EI23) -> 2.3994302
A24: E | B24: 779 | C24: 532 | D24: 86 | E24: 290 | F24: 534 | G24: 505 | H24: 249 | I24: 503 | J24: 991 | K24: 705 | L24: 357 | M24: 112 | N24: 927 | O24: 582 | P24: 746 | Q24: 677 | R24: 405 | S24: 758 | T24: 412 | U24: 890 | V24: 944 | W24: 818 | X24: 293 | Y24: 575 | Z24: 10 | AA24: 294 | AB24: 593 | AC24: 380 | AD24: 133 | AE24: 886 | AF24: 956 | AG24: 886 | AH24: 506 | AI24: 581 | AJ24: 558 | AK24: 879 | AL24: 322 | AM24: 613 | AN24: 613 | AO24: 888 | AP24: 592 | AQ24: 192 | AR24: 249 | AS24: 293 | AT24: 283 | AU24: 156 | AV24: 336 | AW24: 192 | AX24: 226 | AY24: 634 | AZ24: 713 | BA24: 961 | BB24: 41 | BC24: 988 | BD24: 628 | BE24: 286 | BF24: 90 | BG24: 350 | BH24: 312 | BI24: 127 | BJ24: 862 | BK24: 433 | BL24: 311 | BM24: 795 | BN24: 94 | BO24: 249 | BP24: 293 | BQ24: 825 | BR24: 986 | BS24: 360 | BT24: 590 | BU24: 435 | BV24: 713 | BW24: 40 | BX24: 881 | BY24: 942 | BZ24: 910 | CA24: 663 | CB24: 815 | CC24: 523 | CD24: 901 | CE24: 500 | CF24: 637 | CG24: 972 | CH24: 294 | CI24: 815 | CJ24: 860 | CK24: 736 | CL24: 929 | CM24: 650 | CN24: 396 | CO24: 541 | CP24: 471 | CQ24: 370 | CR24: 727 | CS24: 639 | CT24: 626 | CU24: 955 | CV24: 31 | CW24: 250 | CX24: =AVERAGE(CO24:CW24) -> 512.22222 | CY24: =AVERAGE(CP24:CX24) -> 509.02469 | CZ24: =AVERAGE(CQ24:CY24) -> 513.24966 | DA24: =AVERAGE(CR24:CZ24) -> 529.16629 | DB24: =AVERAGE(CS24:DA24) -> 507.18476 | DC24: =AVERAGE(CT24:DB24) -> 492.53862 | DD24: =AVERAGE(CU24:DC24) -> 477.70958 | DE24: =AVERAGE(CV24:DD24) -> 424.67731 | ... DG24: =AVERAGE(CX24:DF24) -> 492.68804 | DI24: =ABS(CX24-CX6) -> 398.77778 | DJ24: =ABS(CY24-CY6) -> 178.97531 | DK24: =ABS(CZ24-CZ6) -> 163.75034 | DL24: =ABS(DA24-DA6) -> 258.83371 | DM24: =ABS(DB24-DB6) -> 142.81524 | DN24: =ABS(DC24-DC6) -> 241.46138 | DO24: =ABS(DD24-DD6) -> 65.290418 | DP24: =ABS(DE24-DE6) -> 87.677314 | ... DR24: =ABS(DG24-DG6) -> 366.68804 | DS24: =SUM(DI24:DR24) -> 1949.8503 | DU24: 9 | DZ24: =ABS(CX24-CX$6)/MAX($B$6:$CW$6) -> 0.40239937 | EA24: =ABS(CY24-CY$6)/MAX($B$6:$CW$6) -> 0.18060072 | EB24: =ABS(CZ24-CZ$6)/MAX($B$6:$CW$6) -> 0.16523748 | EC24: =ABS(DA24-DA$6)/MAX($B$6:$CW$6) -> 0.26118437 | ED24: =ABS(DB24-DB$6)/MAX($B$6:$CW$6) -> 0.14411225 | EE24: =ABS(DC24-DC$6)/MAX($B$6:$CW$6) -> 0.24365426 | EF24: =ABS(DD24-DD$6)/MAX($B$6:$CW$6) -> 0.065883368 | EG24: =ABS(DE24-DE$6)/MAX($B$6:$CW$6) -> 0.088473576 | ... EI24: =ABS(DG24-DG$6)/MAX($B$6:$CW$6) -> 0.37001821 | EJ24: =SUM(DZ24:EI24) -> 1.9675583
CX27: SES
A28: Item | B28: Week1 | C28: Week2 | D28: Week3 | E28: Week4 | F28: Week5 | G28: Week6 | H28: Week7 | I28: Week8 | J28: Week9 | K28: Week10 | L28: Week11 | M28: Week12 | N28: Week13 | O28: Week14 | P28: Week15 | Q28: Week16 | R28: Week17 | S28: Week18 | T28: Week19 | U28: Week20 | V28: Week21 | W28: Week22 | X28: Week23 | Y28: Week24 | Z28: Week25 | AA28: Week26 | AB28: Week27 | AC28: Week28 | AD28: Week29 | AE28: Week30 | AF28: Week31 | AG28: Week32 | AH28: Week33 | AI28: Week34 | AJ28: Week35 | AK28: Week36 | AL28: Week37 | AM28: Week38 | AN28: Week39 | AO28: Week40 | AP28: Week41 | AQ28: Week42 | AR28: Week43 | AS28: Week44 | AT28: Week45 | AU28: Week46 | AV28: Week47 | AW28: Week48 | AX28: Week49 | AY28: Week50 | AZ28: Week51 | BA28: Week52 | BB28: Week53 | BC28: Week54 | BD28: Week55 | BE28: Week56 | BF28: Week57 | BG28: Week58 | BH28: Week59 | BI28: Week60 | BJ28: Week61 | BK28: Week62 | BL28: Week63 | BM28: Week64 | BN28: Week65 | BO28: Week66 | BP28: Week67 | BQ28: Week68 | BR28: Week69 | BS28: Week70 | BT28: Week71 | BU28: Week72 | BV28: Week73 | BW28: Week74 | BX28: Week75 | BY28: Week76 | BZ28: Week77 | CA28: Week78 | CB28: Week79 | CC28: Week80 | CD28: Week81 | CE28: Week82 | CF28: Week83 | CG28: Week84 | CH28: Week85 | CI28: Week86 | CJ28: Week87 | CK28: Week88 | CL28: Week89 | CM28: Week90 | CN28: Week91 | CO28: Week92 | CP28: Week93 | CQ28: Week94 | CR28: Week95 | CS28: Week96 | CT28: Week97 | CU28: Week98 | CV28: Week99 | CW28: Week100 | CX28: Week101 | CY28: Week102 | CZ28: Week103 | DA28: Week104 | DB28: Week105 | DC28: Week106 | DD28: Week107 | DE28: Week108 | DF28: Week109 | DG28: Week110 | DI28: Week101 | DJ28: Week102 | DK28: Week103 | DL28: Week104 | DM28: Week105 | DN28: Week106 | DO28: Week107 | DP28: Week108 | DQ28: Week109 | DR28: Week110 | DS28: Summarized | DU28: Alpha SES | DZ28: Week101 | EA28: Week102 | EB28: Week103 | EC28: Week104 | ED28: Week105 | EE28: Week106 | EF28: Week107 | EG28: Week108 | EH28: Week109 | EI28: Week110 | EJ28: Summarized
A29: A | B29: 3 | C29: 12 | D29: 41 | E29: 2 | F29: 31 | G29: 2 | H29: 43 | I29: 43 | J29: 22 | K29: 32 | L29: 3 | M29: 12 | N29: 41 | O29: 2 | P29: 31 | Q29: 2 | R29: 43 | S29: 43 | T29: 22 | U29: 32 | V29: 3 | W29: 12 | X29: 41 | Y29: 2 | Z29: 31 | AA29: 2 | AB29: 43 | AC29: 43 | AD29: 22 | AE29: 32 | AF29: 3 | AG29: 12 | AH29: 41 | AI29: 2 | AJ29: 31 | AK29: 2 | AL29: 43 | AM29: 43 | AN29: 22 | AO29: 32 | AP29: 3 | AQ29: 12 | AR29: 41 | AS29: 2 | AT29: 31 | AU29: 2 | AV29: 43 | AW29: 43 | AX29: 22 | AY29: 32 | AZ29: 3 | BA29: 12 | BB29: 41 | BC29: 2 | BD29: 31 | BE29: 2 | BF29: 43 | BG29: 43 | BH29: 22 | BI29: 32 | BJ29: 3 | BK29: 12 | BL29: 41 | BM29: 2 | BN29: 31 | BO29: 2 | BP29: 43 | BQ29: 43 | BR29: 22 | BS29: 32 | BT29: 3 | BU29: 12 | BV29: 41 | BW29: 2 | BX29: 31 | BY29: 2 | BZ29: 43 | CA29: 43 | CB29: 22 | CC29: 32 | CD29: 3 | CE29: 12 | CF29: 41 | CG29: 2 | CH29: 31 | CI29: 2 | CJ29: 43 | CK29: 43 | CL29: 22 | CM29: 32 | CN29: 3 | CO29: 12 | CP29: 41 | CQ29: 2 | CR29: 31 | CS29: 2 | CT29: 43 | CU29: 43 | CV29: 22 | CW29: 32 | CX29: =$CW$30 -> 29.7945 | CY29: =$CW$30 -> 29.7945 | CZ29: =$CW$30 -> 29.7945 | DA29: =$CW$30 -> 29.7945 | DB29: =$CW$30 -> 29.7945 | DC29: =$CW$30 -> 29.7945 | DD29: =$CW$30 -> 29.7945 | DE29: =$CW$30 -> 29.7945 | ... DG29: =$CW$30 -> 29.7945 | DI29: =ABS(CX29-CX2) -> 26.7945 | DJ29: =ABS(CY29-CY2) -> 17.7945 | DK29: =ABS(CZ29-CZ2) -> 11.2055 | DL29: =ABS(DA29-DA2) -> 27.7945 | DM29: =ABS(DB29-DB2) -> 1.2054997 | DN29: =ABS(DC29-DC2) -> 27.7945 | DO29: =ABS(DD29-DD2) -> 13.2055 | DP29: =ABS(DE29-DE2) -> 13.2055 | ... DR29: =ABS(DG29-DG2) -> 2.2054997 | DS29: =SUM(DI29:DR29) -> 149 | DU29: 0.396002 | DZ29: =ABS(CX29-CX$2)/MAX($B$2:$CW$2) -> 0.62312791 | EA29: =ABS(CY29-CY$2)/MAX($B$2:$CW$2) -> 0.41382559 | EB29: =ABS(CZ29-CZ$2)/MAX($B$2:$CW$2) -> 0.26059302 | EC29: =ABS(DA29-DA$2)/MAX($B$2:$CW$2) -> 0.64638373 | ED29: =ABS(DB29-DB$2)/MAX($B$2:$CW$2) -> 0.028034876 | EE29: =ABS(DC29-DC$2)/MAX($B$2:$CW$2) -> 0.64638373 | EF29: =ABS(DD29-DD$2)/MAX($B$2:$CW$2) -> 0.30710464 | EG29: =ABS(DE29-DE$2)/MAX($B$2:$CW$2) -> 0.30710464 | ... EI29: =ABS(DG29-DG$2)/MAX($B$2:$CW$2) -> 0.05129069 | EJ29: =SUM(DZ29:EI29) -> 3.4651163
A30: A SES LEVEL | B30: =B29 -> 3 | C30: =$DU$29*C29 + (1-$DU$29)*B30 -> 6.564018 | D30: =$DU$29*D29 + (1-$DU$29)*C30 -> 20.200736 | E30: =$DU$29*E29 + (1-$DU$29)*D30 -> 12.993208 | F30: =$DU$29*F29 + (1-$DU$29)*E30 -> 20.123934 | G30: =$DU$29*G29 + (1-$DU$29)*F30 -> 12.94682 | H30: =$DU$29*H29 + (1-$DU$29)*G30 -> 24.847939 | I30: =$DU$29*I29 + (1-$DU$29)*H30 -> 32.036192 | J30: =$DU$29*J29 + (1-$DU$29)*I30 -> 28.06184 | ... CW30: =$DU$29*CW29 + (1-$DU$29)*CV30 -> 29.7945
A31: B | B31: 0 | C31: 0 | D31: 112 | E31: 2 | F31: 100 | G31: 33 | H31: 55 | I31: 53 | J31: 23 | K31: 12 | L31: 0 | M31: 0 | N31: 112 | O31: 2 | P31: 100 | Q31: 33 | R31: 55 | S31: 53 | T31: 23 | U31: 12 | V31: 0 | W31: 0 | X31: 112 | Y31: 2 | Z31: 100 | AA31: 33 | AB31: 55 | AC31: 53 | AD31: 23 | AE31: 12 | AF31: 0 | AG31: 0 | AH31: 112 | AI31: 2 | AJ31: 100 | AK31: 33 | AL31: 55 | AM31: 53 | AN31: 23 | AO31: 12 | AP31: 0 | AQ31: 0 | AR31: 112 | AS31: 2 | AT31: 100 | AU31: 33 | AV31: 55 | AW31: 53 | AX31: 23 | AY31: 12 | AZ31: 0 | BA31: 0 | BB31: 112 | BC31: 2 | BD31: 100 | BE31: 33 | BF31: 55 | BG31: 53 | BH31: 23 | BI31: 12 | BJ31: 0 | BK31: 0 | BL31: 112 | BM31: 2 | BN31: 100 | BO31: 33 | BP31: 55 | BQ31: 53 | BR31: 23 | BS31: 12 | BT31: 0 | BU31: 0 | BV31: 112 | BW31: 2 | BX31: 100 | BY31: 33 | BZ31: 55 | CA31: 53 | CB31: 23 | CC31: 12 | CD31: 0 | CE31: 0 | CF31: 112 | CG31: 2 | CH31: 100 | CI31: 33 | CJ31: 55 | CK31: 53 | CL31: 23 | CM31: 12 | CN31: 0 | CO31: 0 | CP31: 112 | CQ31: 2 | CR31: 100 | CS31: 33 | CT31: 55 | CU31: 53 | CV31: 23 | CW31: 12 | CX31: =$CW$32 -> 26.227295 | CY31: =$CW$32 -> 26.227295 | CZ31: =$CW$32 -> 26.227295 | DA31: =$CW$32 -> 26.227295 | DB31: =$CW$32 -> 26.227295 | DC31: =$CW$32 -> 26.227295 | DD31: =$CW$32 -> 26.227295 | DE31: =$CW$32 -> 26.227295 | ... DG31: =$CW$32 -> 26.227295 | DI31: =ABS(CX31-CX3) -> 26.227295 | DJ31: =ABS(CY31-CY3) -> 26.227295 | DK31: =ABS(CZ31-CZ3) -> 85.772705 | DL31: =ABS(DA31-DA3) -> 24.227295 | DM31: =ABS(DB31-DB3) -> 73.772705 | DN31: =ABS(DC31-DC3) -> 6.772705 | DO31: =ABS(DD31-DD3) -> 28.772705 | DP31: =ABS(DE31-DE3) -> 26.772705 | ... DR31: =ABS(DG31-DG3) -> 14.227295 | DS31: =SUM(DI31:DR31) -> 316 | DU31: 0.46661021 | DZ31: =ABS(CX31-CX$3)/MAX($B$3:$CW$3) -> 0.23417228 | EA31: =ABS(CY31-CY$3)/MAX($B$3:$CW$3) -> 0.23417228 | EB31: =ABS(CZ31-CZ$3)/MAX($B$3:$CW$3) -> 0.76582772 | EC31: =ABS(DA31-DA$3)/MAX($B$3:$CW$3) -> 0.21631513 | ED31: =ABS(DB31-DB$3)/MAX($B$3:$CW$3) -> 0.65868487 | EE31: =ABS(DC31-DC$3)/MAX($B$3:$CW$3) -> 0.06047058 | EF31: =ABS(DD31-DD$3)/MAX($B$3:$CW$3) -> 0.25689915 | EG31: =ABS(DE31-DE$3)/MAX($B$3:$CW$3) -> 0.23904201 | ... EI31: =ABS(DG31-DG$3)/MAX($B$3:$CW$3) -> 0.12702942 | EJ31: =SUM(DZ31:EI31) -> 2.8214286
A32: B SES LEVEL | B32: =B31 -> 0 | C32: =$DU$31*C31 + (1-$DU$31)*B32 -> 0 | D32: =$DU$31*D31 + (1-$DU$31)*C32 -> 52.260343 | E32: =$DU$31*E31 + (1-$DU$31)*D32 -> 28.808354 | F32: =$DU$31*F31 + (1-$DU$31)*E32 -> 62.027103 | G32: =$DU$31*G31 + (1-$DU$31)*F32 -> 48.48276 | H32: =$DU$31*H31 + (1-$DU$31)*G32 -> 51.523771 | I32: =$DU$31*I31 + (1-$DU$31)*H32 -> 52.212594 | J32: =$DU$31*J31 + (1-$DU$31)*I32 -> 38.5817 | ... CW32: =$DU$31*CW31 + (1-$DU$31)*CV32 -> 26.227295
A33: C | B33: 916 | C33: 939 | D33: 305 | E33: 952 | F33: 128 | G33: 81 | H33: 908 | I33: 744 | J33: 333 | K33: 862 | L33: 606 | M33: 352 | N33: 233 | O33: 502 | P33: 693 | Q33: 828 | R33: 189 | S33: 89 | T33: 705 | U33: 486 | V33: 142 | W33: 575 | X33: 972 | Y33: 222 | Z33: 593 | AA33: 259 | AB33: 492 | AC33: 227 | AD33: 195 | AE33: 374 | AF33: 539 | AG33: 2 | AH33: 865 | AI33: 308 | AJ33: 118 | AK33: 126 | AL33: 881 | AM33: 126 | AN33: 645 | AO33: 868 | AP33: 943 | AQ33: 483 | AR33: 701 | AS33: 190 | AT33: 251 | AU33: 872 | AV33: 905 | AW33: 632 | AX33: 842 | AY33: 42 | AZ33: 517 | BA33: 950 | BB33: 891 | BC33: 536 | BD33: 462 | BE33: 916 | BF33: 939 | BG33: 305 | BH33: 952 | BI33: 128 | BJ33: 81 | BK33: 908 | BL33: 744 | BM33: 333 | BN33: 862 | BO33: 606 | BP33: 352 | BQ33: 233 | BR33: 502 | BS33: 693 | BT33: 828 | BU33: 189 | BV33: 89 | BW33: 705 | BX33: 486 | BY33: 142 | BZ33: 575 | CA33: 972 | CB33: 222 | CC33: 593 | CD33: 259 | CE33: 492 | CF33: 227 | CG33: 195 | CH33: 374 | CI33: 539 | CJ33: 2 | CK33: 865 | CL33: 308 | CM33: 118 | CN33: 126 | CO33: 881 | CP33: 126 | CQ33: 645 | CR33: 868 | CS33: 943 | CT33: 483 | CU33: 701 | CV33: 190 | CW33: 251 | CX33: =$CW$34 -> 658.19622 | CY33: =$CW$34 -> 658.19622 | CZ33: =$CW$34 -> 658.19622 | DA33: =$CW$34 -> 658.19622 | DB33: =$CW$34 -> 658.19622 | DC33: =$CW$34 -> 658.19622 | DD33: =$CW$34 -> 658.19622 | DE33: =$CW$34 -> 658.19622 | ... DG33: =$CW$34 -> 658.19622 | DI33: =ABS(CX33-CX4) -> 213.80378 | DJ33: =ABS(CY33-CY4) -> 246.80378 | DK33: =ABS(CZ33-CZ4) -> 26.196225 | DL33: =ABS(DA33-DA4) -> 183.80378 | DM33: =ABS(DB33-DB4) -> 616.19622 | DN33: =ABS(DC33-DC4) -> 141.19622 | DO33: =ABS(DD33-DD4) -> 291.80378 | DP33: =ABS(DE33-DE4) -> 232.80378 | ... DR33: =ABS(DG33-DG4) -> 196.19622 | DS33: =SUM(DI33:DR33) -> 2271 | DU33: 0.0096064797 | DZ33: =ABS(CX33-CX$4)/MAX($B$4:$CW$4) -> 0.21996273 | EA33: =ABS(CY33-CY$4)/MAX($B$4:$CW$4) -> 0.25391335 | EB33: =ABS(CZ33-CZ$4)/MAX($B$4:$CW$4) -> 0.026950848 | EC33: =ABS(DA33-DA$4)/MAX($B$4:$CW$4) -> 0.18909853 | ED33: =ABS(DB33-DB$4)/MAX($B$4:$CW$4) -> 0.63394673 | EE33: =ABS(DC33-DC$4)/MAX($B$4:$CW$4) -> 0.14526361 | EF33: =ABS(DD33-DD$4)/MAX($B$4:$CW$4) -> 0.30020965 | EG33: =ABS(DE33-DE$4)/MAX($B$4:$CW$4) -> 0.23951006 | ... EI33: =ABS(DG33-DG$4)/MAX($B$4:$CW$4) -> 0.20184797 | EJ33: =SUM(DZ33:EI33) -> 2.3364198
A34: C SES LEVEL | B34: =B33 -> 916 | C34: =$DU$33*C33 + (1-$DU$33)*B34 -> 916.22095 | D34: =$DU$33*D33 + (1-$DU$33)*C34 -> 910.34927 | E34: =$DU$33*E33 + (1-$DU$33)*D34 -> 910.74938 | F34: =$DU$33*F33 + (1-$DU$33)*E34 -> 903.22992 | G34: =$DU$33*G33 + (1-$DU$33)*F34 -> 895.33118 | H34: =$DU$33*H33 + (1-$DU$33)*G34 -> 895.45289 | I34: =$DU$33*I33 + (1-$DU$33)*H34 -> 893.99796 | J34: =$DU$33*J33 + (1-$DU$33)*I34 -> 888.60874 | ... CW34: =$DU$33*CW33 + (1-$DU$33)*CV34 -> 658.19622
A35: D | B35: 77 | C35: 322 | D35: 260 | E35: 233 | F35: 284 | G35: 399 | H35: 370 | I35: 209 | J35: 368 | K35: 240 | L35: 350 | M35: 402 | N35: 343 | O35: 204 | P35: 298 | Q35: 226 | R35: 235 | S35: 4 | T35: 478 | U35: 174 | V35: 451 | W35: 295 | X35: 77 | Y35: 322 | Z35: 260 | AA35: 233 | AB35: 284 | AC35: 399 | AD35: 370 | AE35: 209 | AF35: 368 | AG35: 240 | AH35: 350 | AI35: 402 | AJ35: 343 | AK35: 204 | AL35: 298 | AM35: 226 | AN35: 235 | AO35: 4 | AP35: 478 | AQ35: 174 | AR35: 451 | AS35: 295 | AT35: 77 | AU35: 322 | AV35: 260 | AW35: 233 | AX35: 284 | AY35: 399 | AZ35: 370 | BA35: 209 | BB35: 368 | BC35: 240 | BD35: 350 | BE35: 402 | BF35: 343 | BG35: 204 | BH35: 298 | BI35: 226 | BJ35: 235 | BK35: 4 | BL35: 478 | BM35: 174 | BN35: 451 | BO35: 295 | BP35: 77 | BQ35: 322 | BR35: 260 | BS35: 233 | BT35: 284 | BU35: 399 | BV35: 370 | BW35: 209 | BX35: 368 | BY35: 240 | BZ35: 350 | CA35: 402 | CB35: 343 | CC35: 204 | CD35: 298 | CE35: 226 | CF35: 235 | CG35: 4 | CH35: 478 | CI35: 174 | CJ35: 451 | CK35: 295 | CL35: 77 | CM35: 322 | CN35: 260 | CO35: 233 | CP35: 284 | CQ35: 399 | CR35: 370 | CS35: 209 | CT35: 368 | CU35: 240 | CV35: 350 | CW35: 402 | CX35: =$CW$36 -> 271.79269 | CY35: =$CW$36 -> 271.79269 | CZ35: =$CW$36 -> 271.79269 | DA35: =$CW$36 -> 271.79269 | DB35: =$CW$36 -> 271.79269 | DC35: =$CW$36 -> 271.79269 | DD35: =$CW$36 -> 271.79269 | DE35: =$CW$36 -> 271.79269 | ... DG35: =$CW$36 -> 271.79269 | DI35: =ABS(CX35-CX5) -> 71.207308 | DJ35: =ABS(CY35-CY5) -> 67.792692 | DK35: =ABS(CZ35-CZ5) -> 26.207308 | DL35: =ABS(DA35-DA5) -> 45.792692 | DM35: =ABS(DB35-DB5) -> 36.792692 | DN35: =ABS(DC35-DC5) -> 267.79269 | DO35: =ABS(DD35-DD5) -> 206.20731 | DP35: =ABS(DE35-DE5) -> 97.792692 | ... DR35: =ABS(DG35-DG5) -> 23.207308 | DS35: =SUM(DI35:DR35) -> 1022 | DU35: 0.025382862 | DZ35: =ABS(CX35-CX$5)/MAX($B$5:$CW$5) -> 0.14896926 | EA35: =ABS(CY35-CY$5)/MAX($B$5:$CW$5) -> 0.14182572 | EB35: =ABS(CZ35-CZ$5)/MAX($B$5:$CW$5) -> 0.054827004 | EC35: =ABS(DA35-DA$5)/MAX($B$5:$CW$5) -> 0.095800611 | ED35: =ABS(DB35-DB$5)/MAX($B$5:$CW$5) -> 0.076972159 | EE35: =ABS(DC35-DC$5)/MAX($B$5:$CW$5) -> 0.56023576 | EF35: =ABS(DD35-DD$5)/MAX($B$5:$CW$5) -> 0.43139604 | EG35: =ABS(DE35-DE$5)/MAX($B$5:$CW$5) -> 0.20458722 | ... EI35: =ABS(DG35-DG$5)/MAX($B$5:$CW$5) -> 0.048550854 | EJ35: =SUM(DZ35:EI35) -> 2.1380753
A36: D SES LEVEL | B36: =B35 -> 77 | C36: =$DU$35*C35 + (1-$DU$35)*B36 -> 83.218801 | D36: =$DU$35*D35 + (1-$DU$35)*C36 -> 87.706014 | E36: =$DU$35*E35 + (1-$DU$35)*D36 -> 91.393991 | F36: =$DU$35*F35 + (1-$DU$35)*E36 -> 96.282883 | G36: =$DU$35*G35 + (1-$DU$35)*F36 -> 103.96671 | H36: =$DU$35*H35 + (1-$DU$35)*G36 -> 110.7194 | I36: =$DU$35*I35 + (1-$DU$35)*H36 -> 113.21404 | J36: =$DU$35*J35 + (1-$DU$35)*I36 -> 119.68124 | ... CW36: =$DU$35*CW35 + (1-$DU$35)*CV36 -> 271.79269
A37: E | B37: 779 | C37: 532 | D37: 86 | E37: 290 | F37: 534 | G37: 505 | H37: 249 | I37: 503 | J37: 991 | K37: 705 | L37: 357 | M37: 112 | N37: 927 | O37: 582 | P37: 746 | Q37: 677 | R37: 405 | S37: 758 | T37: 412 | U37: 890 | V37: 944 | W37: 818 | X37: 293 | Y37: 575 | Z37: 10 | AA37: 294 | AB37: 593 | AC37: 380 | AD37: 133 | AE37: 886 | AF37: 956 | AG37: 886 | AH37: 506 | AI37: 581 | AJ37: 558 | AK37: 879 | AL37: 322 | AM37: 613 | AN37: 613 | AO37: 888 | AP37: 592 | AQ37: 192 | AR37: 249 | AS37: 293 | AT37: 283 | AU37: 156 | AV37: 336 | AW37: 192 | AX37: 226 | AY37: 634 | AZ37: 713 | BA37: 961 | BB37: 41 | BC37: 988 | BD37: 628 | BE37: 286 | BF37: 90 | BG37: 350 | BH37: 312 | BI37: 127 | BJ37: 862 | BK37: 433 | BL37: 311 | BM37: 795 | BN37: 94 | BO37: 249 | BP37: 293 | BQ37: 825 | BR37: 986 | BS37: 360 | BT37: 590 | BU37: 435 | BV37: 713 | BW37: 40 | BX37: 881 | BY37: 942 | BZ37: 910 | CA37: 663 | CB37: 815 | CC37: 523 | CD37: 901 | CE37: 500 | CF37: 637 | CG37: 972 | CH37: 294 | CI37: 815 | CJ37: 860 | CK37: 736 | CL37: 929 | CM37: 650 | CN37: 396 | CO37: 541 | CP37: 471 | CQ37: 370 | CR37: 727 | CS37: 639 | CT37: 626 | CU37: 955 | CV37: 31 | CW37: 250 | CX37: =$CW$38 -> 670.66876 | CY37: =$CW$38 -> 670.66876 | CZ37: =$CW$38 -> 670.66876 | DA37: =$CW$38 -> 670.66876 | DB37: =$CW$38 -> 670.66876 | DC37: =$CW$38 -> 670.66876 | DD37: =$CW$38 -> 670.66876 | DE37: =$CW$38 -> 670.66876 | ... DG37: =$CW$38 -> 670.66876 | DI37: =ABS(CX37-CX6) -> 240.33124 | DJ37: =ABS(CY37-CY6) -> 17.331237 | DK37: =ABS(CZ37-CZ6) -> 6.3312375 | DL37: =ABS(DA37-DA6) -> 117.33124 | DM37: =ABS(DB37-DB6) -> 20.668763 | DN37: =ABS(DC37-DC6) -> 63.331237 | DO37: =ABS(DD37-DD6) -> 127.66876 | DP37: =ABS(DE37-DE6) -> 333.66876 | ... DR37: =ABS(DG37-DG6) -> 544.66876 | DS37: =SUM(DI37:DR37) -> 1628 | DU37: 0.0063356943 | DZ37: =ABS(CX37-CX$6)/MAX($B$6:$CW$6) -> 0.24251386 | EA37: =ABS(CY37-CY$6)/MAX($B$6:$CW$6) -> 0.017488635 | EB37: =ABS(CZ37-CZ$6)/MAX($B$6:$CW$6) -> 0.0063887361 | EC37: =ABS(DA37-DA$6)/MAX($B$6:$CW$6) -> 0.11839681 | ED37: =ABS(DB37-DB$6)/MAX($B$6:$CW$6) -> 0.020856471 | EE37: =ABS(DC37-DC$6)/MAX($B$6:$CW$6) -> 0.063906395 | EF37: =ABS(DD37-DD$6)/MAX($B$6:$CW$6) -> 0.12882822 | EG37: =ABS(DE37-DE$6)/MAX($B$6:$CW$6) -> 0.33669905 | ... EI37: =ABS(DG37-DG$6)/MAX($B$6:$CW$6) -> 0.5496153 | EJ37: =SUM(DZ37:EI37) -> 1.6427851
A38: E SES LEVEL | B38: =B37 -> 779 | C38: =$DU$37*C37 + (1-$DU$37)*B38 -> 777.43508 | D38: =$DU$37*D37 + (1-$DU$37)*C38 -> 773.05436 | E38: =$DU$37*E37 + (1-$DU$37)*D38 -> 769.99388 | F38: =$DU$37*F37 + (1-$DU$37)*E38 -> 768.49869 | G38: =$DU$37*G37 + (1-$DU$37)*F38 -> 766.82925 | H38: =$DU$37*H37 + (1-$DU$37)*G38 -> 763.54844 | I38: =$DU$37*I37 + (1-$DU$37)*H38 -> 761.89768 | J38: =$DU$37*J37 + (1-$DU$37)*I38 -> 763.3492 | ... CW38: =$DU$37*CW37 + (1-$DU$37)*CV38 -> 670.66876
CX41: EXP
A42: Item | B42: Week1 | C42: Week2 | D42: Week3 | E42: Week4 | F42: Week5 | G42: Week6 | H42: Week7 | I42: Week8 | J42: Week9 | K42: Week10 | L42: Week11 | M42: Week12 | N42: Week13 | O42: Week14 | P42: Week15 | Q42: Week16 | R42: Week17 | S42: Week18 | T42: Week19 | U42: Week20 | V42: Week21 | W42: Week22 | X42: Week23 | Y42: Week24 | Z42: Week25 | AA42: Week26 | AB42: Week27 | AC42: Week28 | AD42: Week29 | AE42: Week30 | AF42: Week31 | AG42: Week32 | AH42: Week33 | AI42: Week34 | AJ42: Week35 | AK42: Week36 | AL42: Week37 | AM42: Week38 | AN42: Week39 | AO42: Week40 | AP42: Week41 | AQ42: Week42 | AR42: Week43 | AS42: Week44 | AT42: Week45 | AU42: Week46 | AV42: Week47 | AW42: Week48 | AX42: Week49 | AY42: Week50 | AZ42: Week51 | BA42: Week52 | BB42: Week53 | BC42: Week54 | BD42: Week55 | BE42: Week56 | BF42: Week57 | BG42: Week58 | BH42: Week59 | BI42: Week60 | BJ42: Week61 | BK42: Week62 | BL42: Week63 | BM42: Week64 | BN42: Week65 | BO42: Week66 | BP42: Week67 | BQ42: Week68 | BR42: Week69 | BS42: Week70 | BT42: Week71 | BU42: Week72 | BV42: Week73 | BW42: Week74 | BX42: Week75 | BY42: Week76 | BZ42: Week77 | CA42: Week78 | CB42: Week79 | CC42: Week80 | CD42: Week81 | CE42: Week82 | CF42: Week83 | CG42: Week84 | CH42: Week85 | CI42: Week86 | CJ42: Week87 | CK42: Week88 | CL42: Week89 | CM42: Week90 | CN42: Week91 | CO42: Week92 | CP42: Week93 | CQ42: Week94 | CR42: Week95 | CS42: Week96 | CT42: Week97 | CU42: Week98 | CV42: Week99 | CW42: Week100 | CX42: Week101 | CY42: Week102 | CZ42: Week103 | DA42: Week104 | DB42: Week105 | DC42: Week106 | DD42: Week107 | DE42: Week108 | DF42: Week109 | DG42: Week110 | DI42: Week101 | DJ42: Week102 | DK42: Week103 | DL42: Week104 | DM42: Week105 | DN42: Week106 | DO42: Week107 | DP42: Week108 | DQ42: Week109 | DR42: Week110 | DS42: Summarized | DU42: Alpha HOLT | DV42: Beta HOLT | DZ42: Week101 | EA42: Week102 | EB42: Week103 | EC42: Week104 | ED42: Week105 | EE42: Week106 | EF42: Week107 | EG42: Week108 | EH42: Week109 | EI42: Week110 | EJ42: Summarized
A43: A | B43: 3 | C43: 12 | D43: 41 | E43: 2 | F43: 31 | G43: 2 | H43: 43 | I43: 43 | J43: 22 | K43: 32 | L43: 3 | M43: 12 | N43: 41 | O43: 2 | P43: 31 | Q43: 2 | R43: 43 | S43: 43 | T43: 22 | U43: 32 | V43: 3 | W43: 12 | X43: 41 | Y43: 2 | Z43: 31 | AA43: 2 | AB43: 43 | AC43: 43 | AD43: 22 | AE43: 32 | AF43: 3 | AG43: 12 | AH43: 41 | AI43: 2 | AJ43: 31 | AK43: 2 | AL43: 43 | AM43: 43 | AN43: 22 | AO43: 32 | AP43: 3 | AQ43: 12 | AR43: 41 | AS43: 2 | AT43: 31 | AU43: 2 | AV43: 43 | AW43: 43 | AX43: 22 | AY43: 32 | AZ43: 3 | BA43: 12 | BB43: 41 | BC43: 2 | BD43: 31 | BE43: 2 | BF43: 43 | BG43: 43 | BH43: 22 | BI43: 32 | BJ43: 3 | BK43: 12 | BL43: 41 | BM43: 2 | BN43: 31 | BO43: 2 | BP43: 43 | BQ43: 43 | BR43: 22 | BS43: 32 | BT43: 3 | BU43: 12 | BV43: 41 | BW43: 2 | BX43: 31 | BY43: 2 | BZ43: 43 | CA43: 43 | CB43: 22 | CC43: 32 | CD43: 3 | CE43: 12 | CF43: 41 | CG43: 2 | CH43: 31 | CI43: 2 | CJ43: 43 | CK43: 43 | CL43: 22 | CM43: 32 | CN43: 3 | CO43: 12 | CP43: 41 | CQ43: 2 | CR43: 31 | CS43: 2 | CT43: 43 | CU43: 43 | CV43: 22 | CW43: 32 | CX43: =$CW44 + CX44*$CW45 -> 9.4996787 | CY43: =$CW44 + CY44*$CW45 -> 11.999715 | CZ43: =$CW44 + CZ44*$CW45 -> 14.499751 | DA43: =$CW44 + DA44*$CW45 -> 16.999787 | DB43: =$CW44 + DB44*$CW45 -> 19.499823 | DC43: =$CW44 + DC44*$CW45 -> 21.999859 | DD43: =$CW44 + DD44*$CW45 -> 24.499895 | DE43: =$CW44 + DE44*$CW45 -> 26.999931 | ... DG43: =$CW44 + DG44*$CW45 -> 32.000003 | DI43: =ABS(CX43-CX2) -> 6.4996787 | DJ43: =ABS(CY43-CY2) -> 0.00028525108 | DK43: =ABS(CZ43-CZ2) -> 26.500249 | DL43: =ABS(DA43-DA2) -> 14.999787 | DM43: =ABS(DB43-DB2) -> 11.500177 | DN43: =ABS(DC43-DC2) -> 19.999859 | DO43: =ABS(DD43-DD2) -> 18.500105 | DP43: =ABS(DE43-DE2) -> 16.000069 | ... DR43: =ABS(DG43-DG2) -> 2.8983515e-06 | DS43: =SUM(DI43:DR43) -> 121.50018 | DU43: 0.02264417 | DV43: 0.65672797 | DZ43: =ABS(CX43-CX$2)/MAX($B$2:$CW$2) -> 0.15115532 | EA43: =ABS(CY43-CY$2)/MAX($B$2:$CW$2) -> 6.633746e-06 | EB43: =ABS(CZ43-CZ$2)/MAX($B$2:$CW$2) -> 0.61628487 | EC43: =ABS(DA43-DA$2)/MAX($B$2:$CW$2) -> 0.34883225 | ED43: =ABS(DB43-DB$2)/MAX($B$2:$CW$2) -> 0.26744598 | EE43: =ABS(DC43-DC$2)/MAX($B$2:$CW$2) -> 0.465113 | EF43: =ABS(DD43-DD$2)/MAX($B$2:$CW$2) -> 0.430235 | EG43: =ABS(DE43-DE$2)/MAX($B$2:$CW$2) -> 0.37209463 | ... EI43: =ABS(DG43-DG$2)/MAX($B$2:$CW$2) -> 6.7403524e-08 | EJ43: =SUM(DZ43:EI43) -> 2.8255856
A44: A HOLT LEVEL | B44: =B43 -> 3 | C44: =$DU$43*C43 + (1-$DU$43)*(B44 + B45) -> 12 | D44: =$DU$43*D43 + (1-$DU$43)*(C44 + C45) -> 21.452883 | E44: =$DU$43*E43 + (1-$DU$43)*(D44 + D45) -> 30.099278 | F44: =$DU$43*F43 + (1-$DU$43)*(E44 + E45) -> 38.788697 | G44: =$DU$43*G43 + (1-$DU$43)*(F44 + F45) -> 46.508844 | H44: =$DU$43*H43 + (1-$DU$43)*(G44 + G45) -> 54.320692 | I44: =$DU$43*I43 + (1-$DU$43)*(H44 + H45) -> 61.787296 | J44: =$DU$43*J43 + (1-$DU$43)*(I44 + I45) -> 68.329911 | ... CW44: =$DU$43*CW43 + (1-$DU$43)*(CV44 + CV45) -> 6.9996427 | CX44: 1 | CY44: 2 | CZ44: 3 | DA44: 4 | DB44: 5 | DC44: 6 | DD44: 7 | DE44: 8 | DF44: 9 | DG44: 10
A45: A HOLT TREND | B45: =C43 - B43 -> 9 | C45: =$DV$43*(C44 - B44) + (1-$DV$43)*B45 -> 9 | D45: =$DV$43*(D44 - C44) + (1-$DV$43)*C45 -> 9.2974212 | E45: =$DV$43*(E44 - D44) + (1-$DV$43)*D45 -> 8.8698737 | F45: =$DV$43*(F44 - E44) + (1-$DV$43)*E45 -> 8.751364 | G45: =$DV$43*(G44 - F44) + (1-$DV$43)*F45 -> 8.074135 | H45: =$DV$43*(H44 - G44) + (1-$DV$43)*G45 -> 7.9018838 | I45: =$DV$43*(I44 - H44) + (1-$DV$43)*H45 -> 7.6160237 | J45: =$DV$43*(J44 - I44) + (1-$DV$43)*I45 -> 6.9110861 | ... CW45: =$DV$43*(CW44 - CV44) + (1-$DV$43)*CV45 -> 2.500036
A46: B | B46: 0.01 | C46: 0 | D46: 112 | E46: 2 | F46: 100 | G46: 33 | H46: 55 | I46: 53 | J46: 23 | K46: 12 | L46: 0 | M46: 0 | N46: 112 | O46: 2 | P46: 100 | Q46: 33 | R46: 55 | S46: 53 | T46: 23 | U46: 12 | V46: 0 | W46: 0 | X46: 112 | Y46: 2 | Z46: 100 | AA46: 33 | AB46: 55 | AC46: 53 | AD46: 23 | AE46: 12 | AF46: 0 | AG46: 0 | AH46: 112 | AI46: 2 | AJ46: 100 | AK46: 33 | AL46: 55 | AM46: 53 | AN46: 23 | AO46: 12 | AP46: 0 | AQ46: 0 | AR46: 112 | AS46: 2 | AT46: 100 | AU46: 33 | AV46: 55 | AW46: 53 | AX46: 23 | AY46: 12 | AZ46: 0 | BA46: 0 | BB46: 112 | BC46: 2 | BD46: 100 | BE46: 33 | BF46: 55 | BG46: 53 | BH46: 23 | BI46: 12 | BJ46: 0 | BK46: 0 | BL46: 112 | BM46: 2 | BN46: 100 | BO46: 33 | BP46: 55 | BQ46: 53 | BR46: 23 | BS46: 12 | BT46: 0 | BU46: 0 | BV46: 112 | BW46: 2 | BX46: 100 | BY46: 33 | BZ46: 55 | CA46: 53 | CB46: 23 | CC46: 12 | CD46: 0 | CE46: 0 | CF46: 112 | CG46: 2 | CH46: 100 | CI46: 33 | CJ46: 55 | CK46: 53 | CL46: 23 | CM46: 12 | CN46: 0 | CO46: 0 | CP46: 112 | CQ46: 2 | CR46: 100 | CS46: 33 | CT46: 55 | CU46: 53 | CV46: 23 | CW46: 12 | CX46: =$CW47 + CX47*$CW48 -> 0.1842788 | CY46: =$CW47 + CY47*$CW48 -> 0.18955409 | CZ46: =$CW47 + CZ47*$CW48 -> 0.19482938 | DA46: =$CW47 + DA47*$CW48 -> 0.20010467 | DB46: =$CW47 + DB47*$CW48 -> 0.20537996 | DC46: =$CW47 + DC47*$CW48 -> 0.21065525 | DD46: =$CW47 + DD47*$CW48 -> 0.21593053 | DE46: =$CW47 + DE47*$CW48 -> 0.22120582 | ... DG46: =$CW47 + DG47*$CW48 -> 0.2317564 | DI46: =ABS(CX46-CX3) -> 0.1842788 | DJ46: =ABS(CY46-CY3) -> 0.18955409 | DK46: =ABS(CZ46-CZ3) -> 111.80517 | DL46: =ABS(DA46-DA3) -> 1.7998953 | DM46: =ABS(DB46-DB3) -> 99.79462 | DN46: =ABS(DC46-DC3) -> 32.789345 | DO46: =ABS(DD46-DD3) -> 54.784069 | DP46: =ABS(DE46-DE3) -> 52.778794 | ... DR46: =ABS(DG46-DG3) -> 11.768244 | DS46: =SUM(DI46:DR46) -> 388.66749 | DU46: 0.0017869606 | DV46: 0.978542 | DZ46: =ABS(CX46-CX$3)/MAX($B$3:$CW$3) -> 0.0016453465 | EA46: =ABS(CY46-CY$3)/MAX($B$3:$CW$3) -> 0.0016924473 | EB46: =ABS(CZ46-CZ$3)/MAX($B$3:$CW$3) -> 0.99826045 | EC46: =ABS(DA46-DA$3)/MAX($B$3:$CW$3) -> 0.016070494 | ED46: =ABS(DB46-DB$3)/MAX($B$3:$CW$3) -> 0.89102339 | EE46: =ABS(DC46-DC$3)/MAX($B$3:$CW$3) -> 0.29276201 | EF46: =ABS(DD46-DD$3)/MAX($B$3:$CW$3) -> 0.48914348 | EG46: =ABS(DE46-DE$3)/MAX($B$3:$CW$3) -> 0.47123923 | ... EI46: =ABS(DG46-DG$3)/MAX($B$3:$CW$3) -> 0.1050736 | EJ46: =SUM(DZ46:EI46) -> 3.4702454
A47: B HOLT LEVEL | B47: =B46 -> 0.01 | C47: =$DU$3*C46 + (1-$DU$46)*(B47 + B48) -> 0 | D47: =$DU$3*D46 + (1-$DU$46)*(C47 + C48) -> -0.0099821304 | E47: =$DU$3*E46 + (1-$DU$46)*(D47 + D48) -> -0.019928968 | F47: =$DU$3*F46 + (1-$DU$46)*(E47 + E48) -> -0.029823183 | G47: =$DU$3*G46 + (1-$DU$46)*(F47 + F48) -> -0.039647569 | H47: =$DU$3*H46 + (1-$DU$46)*(G47 + G48) -> -0.04938507 | I47: =$DU$3*I46 + (1-$DU$46)*(H47 + H48) -> -0.059018815 | J47: =$DU$3*J46 + (1-$DU$46)*(I47 + I48) -> -0.068532143 | ... CW47: =$DU$3*CW46 + (1-$DU$46)*(CV47 + CV48) -> 0.17900352 | CX47: 1 | CY47: 2 | CZ47: 3 | DA47: 4 | DB47: 5 | DC47: 6 | DD47: 7 | DE47: 8 | DF47: 9 | DG47: 10
A48: B HOLT TREND | B48: =C46 - B46 -> -0.01 | C48: =$DV$46*(C47 - B47) + (1-$DV$46)*B48 -> -0.01 | D48: =$DV$46*(D47 - C47) + (1-$DV$46)*C48 -> -0.0099825138 | E48: =$DV$46*(E47 - D47) + (1-$DV$46)*D48 -> -0.0099476033 | F48: =$DV$46*(F47 - E47) + (1-$DV$46)*E48 -> -0.0098953607 | G48: =$DV$46*(G47 - F47) + (1-$DV$46)*F48 -> -0.0098259082 | H48: =$DV$46*(H47 - G47) + (1-$DV$46)*G48 -> -0.0097393981 | I48: =$DV$46*(I47 - H47) + (1-$DV$46)*H48 -> -0.0096360121 | J48: =$DV$46*(J47 - I47) + (1-$DV$46)*I48 -> -0.0095159612 | ... CW48: =$DV$46*(CW47 - CV47) + (1-$DV$46)*CV48 -> 0.0052752882
...

Sheet Summary and comparion
A2: Item | B2: W101 | C2: W102 | D2: W103 | E2: W104 | F2: W105 | G2: W106 | H2: W107 | I2: W108 | J2: W109 | K2: W110
A3: A | B3: 3 | C3: 12 | D3: 41 | E3: 2 | F3: 31 | G3: 2 | H3: 43 | I3: 43 | J3: 22 | K3: 32
A4: B | B4: 0 | C4: 0 | D4: 112 | E4: 2 | F4: 100 | G4: 33 | H4: 55 | I4: 53 | J4: 23 | K4: 12
A5: C | B5: 872 | C5: 905 | D5: 632 | E5: 842 | F5: 42 | G5: 517 | H5: 950 | I5: 891 | J5: 536 | K5: 462
A6: D | B6: 343 | C6: 204 | D6: 298 | E6: 226 | F6: 235 | G6: 4 | H6: 478 | I6: 174 | J6: 451 | K6: 295
A7: E | B7: 911 | C7: 688 | D7: 677 | E7: 788 | F7: 650 | G7: 734 | H7: 543 | I7: 337 | J7: 514 | K7: 126
B10: Naive
A11: Item | B11: W101 | C11: W102 | D11: W103 | E11: W104 | F11: W105 | G11: W106 | H11: W107 | I11: W108 | J11: W109 | K11: W110
